<?xml version="1.0" ?>
<!-- =================================================================================== -->
<!-- |    This document was autogenerated by xacro from autoXACRO.xacro                | -->
<!-- |    EDITING THIS FILE BY HAND IS NOT RECOMMENDED                                 | -->
<!-- =================================================================================== -->
<robot name="modular_robot_compiled" xmlns:xacro="http://www.ros.org/wiki/xacro">
  <link name="fix_base"/>
  <link name="cylinder_base_M0">
    <inertial>
      <origin rpy="0 0 0" xyz="0 0 0"/>
      <mass value=".3"/>
      <inertia ixx=".0001" ixy="0" ixz="0" iyy=".0001" iyz="0" izz=".0001"/>
    </inertial>
    <visual>
      <geometry>
        <cylinder length="0.05" radius="0.02"/>
      </geometry>
    </visual>
    <collision>
      <geometry>
        <cylinder length="0.05" radius="0.02"/>
      </geometry>
    </collision>
    <material name="">
      <color rgba="0.25098 0.25098 0.25098 1"/>
    </material>
  </link>
  <joint name="module_0_attachment" type="fixed">
    <origin rpy="0 0 0" xyz="0 0 0"/>
    <parent link="fix_base"/>
    <child link="cylinder_base_M0"/>
  </joint>
  <link name="cube_base_M1">
    <inertial>
      <origin rpy="0 0 0" xyz="0 0 0"/>
      <mass value=".3"/>
      <inertia ixx=".0001" ixy="0" ixz="0" iyy=".0010" iyz="0" izz=".0001"/>
    </inertial>
    <visual>
      <geometry>
        <box size=".05 .05 .05"/>
      </geometry>
    </visual>
    <collision>
      <geometry>
        <box size=".05 .05 .05"/>
      </geometry>
    </collision>
    <material name="">
      <color rgba="0.79216 0.81961 0.93333 1"/>
    </material>
  </link>
  <joint name="module_1_attachment" type="fixed">
    <origin rpy="0 0 -1.57079632679" xyz="0 0 0.05"/>
    <parent link="cylinder_base_M0"/>
    <child link="cube_base_M1"/>
  </joint>
  <link name="cylinder_base_M2">
    <inertial>
      <origin rpy="0 0 0" xyz="0 0 0"/>
      <mass value=".3"/>
      <inertia ixx=".0001" ixy="0" ixz="0" iyy=".0001" iyz="0" izz=".0001"/>
    </inertial>
    <visual>
      <geometry>
        <cylinder length="0.05" radius="0.02"/>
      </geometry>
    </visual>
    <collision>
      <geometry>
        <cylinder length="0.05" radius="0.02"/>
      </geometry>
    </collision>
    <material name="">
      <color rgba="0.25098 0.25098 0.25098 1"/>
    </material>
  </link>
  <joint name="module_2_attachment" type="fixed">
    <origin rpy="0 0 3.14159265359" xyz="0 0 0.05"/>
    <parent link="cube_base_M1"/>
    <child link="cylinder_base_M2"/>
  </joint>
  <link name="bendy_input_M3">
    <inertial>
      <origin rpy="0 0 0" xyz="0.03 0 0"/>
      <mass value=".3"/>
      <inertia ixx=".0001" ixy="0" ixz="0" iyy=".0001" iyz="0" izz=".0001"/>
    </inertial>
    <visual>
      <geometry>
        <mesh filename="Rotary_Module1.STL"/>
      </geometry>
    </visual>
    <collision>
      <geometry>
        <mesh filename="Rotary_Module1.STL"/>
      </geometry>
    </collision>
    <material name="">
      <color rgba="0.9 0.9 0.9 1"/>
    </material>
  </link>
  <link name="bendy_output_M3">
    <inertial>
      <origin rpy="0 0 0" xyz="0.0075 0 0"/>
      <mass value=".110"/>
      <inertia ixx=".00001" ixy="0" ixz="0" iyy=".00001" iyz="0" izz=".00001"/>
    </inertial>
    <visual>
      <geometry>
        <mesh filename="Rotary_Module2.STL"/>
      </geometry>
    </visual>
    <collision>
      <geometry>
        <mesh filename="Rotary_Module2.STL"/>
      </geometry>
    </collision>
    <material name="">
      <color rgba="0.9 0.9 0.9 1"/>
    </material>
  </link>
  <joint name="bendy_joint_M3" type="continuous">
    <parent link="bendy_input_M3"/>
    <child link="bendy_output_M3"/>
    <origin rpy="0 0 0" xyz="0.0383 0 0"/>
  </joint>
  <joint name="module_3_attachment" type="fixed">
    <origin rpy="0 0 0" xyz="0 0 0.05"/>
    <parent link="cylinder_base_M2"/>
    <child link="bendy_input_M3"/>
  </joint>
</robot>
