<?xml version="1.0" ?>
<!-- =================================================================================== -->
<!-- |    This document was autogenerated by xacro from /home/cobracommander/catkin_ws/src/eigenbot/urdf/autoXACRO.xacro | -->
<!-- |    EDITING THIS FILE BY HAND IS NOT RECOMMENDED                                 | -->
<!-- =================================================================================== -->
<robot name="modular_robot_compiled" xmlns:xacro="http://www.ros.org/wiki/xacro">
  <link name="wheel_input_M0_SF1">
    <inertial>
      <origin rpy="0 0 0" xyz="-0.03217 -0.01684  0.00008"/>
      <mass value="0.16899"/>
      <inertia ixx="0.00011469" ixy="0.00005233" ixz="0.0000004" iyy="0.00011843" iyz="0.00000024" izz="0.00017019"/>
    </inertial>
    <visual>
      <geometry>
        <mesh filename="package://eigenbot/meshes/Wheel In.STL" scale=" 1 1 1 "/>
      </geometry>
    </visual>
    <collision>
      <geometry>
        <mesh filename="package://eigenbot/meshes/Wheel In.STL" scale=" 1 1 1 "/>
      </geometry>
    </collision>
    <material name="black">
      <color rgba="0.1 0.1 0.1 1"/>
    </material>
  </link>
  <link name="wheel_output_M0_SF1">
    <inertial>
      <origin rpy="0 0 0" xyz="-0.03 0 0"/>
      <mass value="0.30808"/>
      <inertia ixx=".00103" ixy="0" ixz="0" iyy="0.00054" iyz="0" izz="0.00054"/>
    </inertial>
    <visual>
      <geometry>
        <mesh filename="package://eigenbot/meshes/Wheel Out.STL" scale=" 1 1 1 "/>
      </geometry>
      <origin rpy="0 0 0" xyz="0 0 0"/>
    </visual>
    <collision>
      <geometry>
        <mesh filename="package://eigenbot/meshes/Wheel Out.STL" scale=" 1 1 1 "/>
      </geometry>
    </collision>
    <material name="black">
      <color rgba="0.1 0.1 0.1 1"/>
    </material>
  </link>
  <joint name="wheel_joint_M0_SF1" type="continuous">
    <parent link="wheel_input_M0_SF1"/>
    <child link="wheel_output_M0_SF1"/>
    <origin rpy="0 0 0" xyz="-0.06858 -0.044775 0"/>
    <axis xyz="1 0 0"/>
    <limit effort="100.0" velocity="3.2"/>
  </joint>
  <link name="wheel_input_M1_SF3">
    <inertial>
      <origin rpy="0 0 0" xyz="-0.03217 -0.01684  0.00008"/>
      <mass value="0.16899"/>
      <inertia ixx="0.00011469" ixy="0.00005233" ixz="0.0000004" iyy="0.00011843" iyz="0.00000024" izz="0.00017019"/>
    </inertial>
    <visual>
      <geometry>
        <mesh filename="package://eigenbot/meshes/Wheel In.STL" scale=" 1 1 1 "/>
      </geometry>
    </visual>
    <collision>
      <geometry>
        <mesh filename="package://eigenbot/meshes/Wheel In.STL" scale=" 1 1 1 "/>
      </geometry>
    </collision>
    <material name="black">
      <color rgba="0.1 0.1 0.1 1"/>
    </material>
  </link>
  <link name="wheel_output_M1_SF3">
    <inertial>
      <origin rpy="0 0 0" xyz="-0.03 0 0"/>
      <mass value="0.30808"/>
      <inertia ixx=".00103" ixy="0" ixz="0" iyy="0.00054" iyz="0" izz="0.00054"/>
    </inertial>
    <visual>
      <geometry>
        <mesh filename="package://eigenbot/meshes/Wheel Out.STL" scale=" 1 1 1 "/>
      </geometry>
      <origin rpy="0 0 0" xyz="0 0 0"/>
    </visual>
    <collision>
      <geometry>
        <mesh filename="package://eigenbot/meshes/Wheel Out.STL" scale=" 1 1 1 "/>
      </geometry>
    </collision>
    <material name="black">
      <color rgba="0.1 0.1 0.1 1"/>
    </material>
  </link>
  <joint name="wheel_joint_M1_SF3" type="continuous">
    <parent link="wheel_input_M1_SF3"/>
    <child link="wheel_output_M1_SF3"/>
    <origin rpy="0 0 0" xyz="-0.06858 -0.044775 0"/>
    <axis xyz="1 0 0"/>
    <limit effort="100.0" velocity="3.2"/>
  </joint>
  <link name="foot_input_M2_S47">
    <inertial>
      <origin rpy="0 0 0" xyz="-0.03918 0 0"/>
      <mass value="0.04967"/>
      <inertia ixx="0.0000361" ixy="0" ixz="0" iyy="0.0000434" iyz="0" izz="0.0000434"/>
    </inertial>
    <visual>
      <geometry>
        <mesh filename="package://eigenbot/meshes/Foot.STL" scale=" 1 1 1 "/>
      </geometry>
    </visual>
    <collision>
      <geometry>
        <mesh filename="package://eigenbot/meshes/Foot.STL" scale=" 1 1 1 "/>
      </geometry>
    </collision>
    <material name="black">
      <color rgba="0.1 0.1 0.1 1"/>
    </material>
  </link>
  <link name="bendy_input_M3_S02">
    <inertial>
      <origin rpy="0 0 0" xyz="-0.023 0 0"/>
      <mass value="0.13536"/>
      <inertia ixx="0.000047004" ixy="-0.000000049" ixz="0.000000017" iyy="0.000068413" iyz="0.000000009" izz="0.000070686"/>
    </inertial>
    <visual>
      <geometry>
        <mesh filename="package://eigenbot/meshes/Bendy In.STL" scale="1 1 1"/>
      </geometry>
    </visual>
    <collision>
      <geometry>
        <mesh filename="package://eigenbot/meshes/Bendy In.STL" scale="1 1 1"/>
      </geometry>
    </collision>
    <material name="black">
      <color rgba="0.1 0.1 0.1 1"/>
    </material>
  </link>
  <link name="bendy_output_M3_S02">
    <inertial>
      <origin rpy="0 0 0" xyz="-0.029 0 0"/>
      <mass value=".03522"/>
      <inertia ixx="0.000021977" ixy="0.000000082" ixz="-0.000000063" iyy="0.000017473" iyz="0.000000067" izz="0.000021078"/>
    </inertial>
    <visual>
      <geometry>
        <mesh filename="package://eigenbot/meshes/Bendy Out.STL" scale="1 1 1"/>
      </geometry>
      <origin rpy="0 0 0" xyz="0 0 0 "/>
    </visual>
    <collision>
      <geometry>
        <mesh filename="package://eigenbot/meshes/Bendy Out.STL" scale="1 1 1"/>
      </geometry>
      <origin rpy="0 0 0" xyz="0 0 0"/>
    </collision>
    <material name="black">
      <color rgba="0.1 0.1 0.1 1"/>
    </material>
  </link>
  <joint name="bendy_joint_M3_S02" type="revolute">
    <parent link="bendy_input_M3_S02"/>
    <child link="bendy_output_M3_S02"/>
    <origin rpy="0 0 0" xyz="-0.049 0 0"/>
    <axis xyz="0 1 0"/>
    <limit effort="100.0" lower="-1.57079632679" upper="1.57079632679" velocity="5"/>
  </joint>
  <link name="static_elbow_M4_S42">
    <inertial>
      <origin rpy="0 0 0" xyz="-0.03148 0.00004 -0.01437"/>
      <mass value="0.06766"/>
      <inertia ixx="0.000052397" ixy="-0.0000001126" ixz="0.000015681" iyy="0.000065586" iyz="-0.000000082" izz="0.000053626"/>
    </inertial>
    <visual>
      <geometry>
        <mesh filename="package://eigenbot/meshes/Elbow.STL" scale="1 1 1"/>
      </geometry>
      <origin rpy="-1.57079632679 0 0" xyz="0 0 0"/>
    </visual>
    <collision>
      <geometry>
        <mesh filename="package://eigenbot/meshes/Elbow.STL" scale="1 1 1"/>
      </geometry>
      <origin rpy="-1.57079632679 0 0" xyz="0 0 0"/>
    </collision>
    <material name="black">
      <color rgba="0.1 0.1 0.1 1"/>
    </material>
  </link>
  <link name="bendy_input_M5_S1D">
    <inertial>
      <origin rpy="0 0 0" xyz="-0.023 0 0"/>
      <mass value="0.13536"/>
      <inertia ixx="0.000047004" ixy="-0.000000049" ixz="0.000000017" iyy="0.000068413" iyz="0.000000009" izz="0.000070686"/>
    </inertial>
    <visual>
      <geometry>
        <mesh filename="package://eigenbot/meshes/Bendy In.STL" scale="1 1 1"/>
      </geometry>
    </visual>
    <collision>
      <geometry>
        <mesh filename="package://eigenbot/meshes/Bendy In.STL" scale="1 1 1"/>
      </geometry>
    </collision>
    <material name="black">
      <color rgba="0.1 0.1 0.1 1"/>
    </material>
  </link>
  <link name="bendy_output_M5_S1D">
    <inertial>
      <origin rpy="0 0 0" xyz="-0.029 0 0"/>
      <mass value=".03522"/>
      <inertia ixx="0.000021977" ixy="0.000000082" ixz="-0.000000063" iyy="0.000017473" iyz="0.000000067" izz="0.000021078"/>
    </inertial>
    <visual>
      <geometry>
        <mesh filename="package://eigenbot/meshes/Bendy Out.STL" scale="1 1 1"/>
      </geometry>
      <origin rpy="0 0 0" xyz="0 0 0 "/>
    </visual>
    <collision>
      <geometry>
        <mesh filename="package://eigenbot/meshes/Bendy Out.STL" scale="1 1 1"/>
      </geometry>
      <origin rpy="0 0 0" xyz="0 0 0"/>
    </collision>
    <material name="black">
      <color rgba="0.1 0.1 0.1 1"/>
    </material>
  </link>
  <joint name="bendy_joint_M5_S1D" type="revolute">
    <parent link="bendy_input_M5_S1D"/>
    <child link="bendy_output_M5_S1D"/>
    <origin rpy="0 0 0" xyz="-0.049 0 0"/>
    <axis xyz="0 1 0"/>
    <limit effort="100.0" lower="-1.57079632679" upper="1.57079632679" velocity="5"/>
  </joint>
  <link name="bendy_input_M6_S53">
    <inertial>
      <origin rpy="0 0 0" xyz="-0.023 0 0"/>
      <mass value="0.13536"/>
      <inertia ixx="0.000047004" ixy="-0.000000049" ixz="0.000000017" iyy="0.000068413" iyz="0.000000009" izz="0.000070686"/>
    </inertial>
    <visual>
      <geometry>
        <mesh filename="package://eigenbot/meshes/Bendy In.STL" scale="1 1 1"/>
      </geometry>
    </visual>
    <collision>
      <geometry>
        <mesh filename="package://eigenbot/meshes/Bendy In.STL" scale="1 1 1"/>
      </geometry>
    </collision>
    <material name="black">
      <color rgba="0.1 0.1 0.1 1"/>
    </material>
  </link>
  <link name="bendy_output_M6_S53">
    <inertial>
      <origin rpy="0 0 0" xyz="-0.029 0 0"/>
      <mass value=".03522"/>
      <inertia ixx="0.000021977" ixy="0.000000082" ixz="-0.000000063" iyy="0.000017473" iyz="0.000000067" izz="0.000021078"/>
    </inertial>
    <visual>
      <geometry>
        <mesh filename="package://eigenbot/meshes/Bendy Out.STL" scale="1 1 1"/>
      </geometry>
      <origin rpy="0 0 0" xyz="0 0 0 "/>
    </visual>
    <collision>
      <geometry>
        <mesh filename="package://eigenbot/meshes/Bendy Out.STL" scale="1 1 1"/>
      </geometry>
      <origin rpy="0 0 0" xyz="0 0 0"/>
    </collision>
    <material name="black">
      <color rgba="0.1 0.1 0.1 1"/>
    </material>
  </link>
  <joint name="bendy_joint_M6_S53" type="revolute">
    <parent link="bendy_input_M6_S53"/>
    <child link="bendy_output_M6_S53"/>
    <origin rpy="0 0 0" xyz="-0.049 0 0"/>
    <axis xyz="0 1 0"/>
    <limit effort="100.0" lower="-1.57079632679" upper="1.57079632679" velocity="5"/>
  </joint>
  <link name="bendy_input_M7_SC0">
    <inertial>
      <origin rpy="0 0 0" xyz="-0.023 0 0"/>
      <mass value="0.13536"/>
      <inertia ixx="0.000047004" ixy="-0.000000049" ixz="0.000000017" iyy="0.000068413" iyz="0.000000009" izz="0.000070686"/>
    </inertial>
    <visual>
      <geometry>
        <mesh filename="package://eigenbot/meshes/Bendy In.STL" scale="1 1 1"/>
      </geometry>
    </visual>
    <collision>
      <geometry>
        <mesh filename="package://eigenbot/meshes/Bendy In.STL" scale="1 1 1"/>
      </geometry>
    </collision>
    <material name="black">
      <color rgba="0.1 0.1 0.1 1"/>
    </material>
  </link>
  <link name="bendy_output_M7_SC0">
    <inertial>
      <origin rpy="0 0 0" xyz="-0.029 0 0"/>
      <mass value=".03522"/>
      <inertia ixx="0.000021977" ixy="0.000000082" ixz="-0.000000063" iyy="0.000017473" iyz="0.000000067" izz="0.000021078"/>
    </inertial>
    <visual>
      <geometry>
        <mesh filename="package://eigenbot/meshes/Bendy Out.STL" scale="1 1 1"/>
      </geometry>
      <origin rpy="0 0 0" xyz="0 0 0 "/>
    </visual>
    <collision>
      <geometry>
        <mesh filename="package://eigenbot/meshes/Bendy Out.STL" scale="1 1 1"/>
      </geometry>
      <origin rpy="0 0 0" xyz="0 0 0"/>
    </collision>
    <material name="black">
      <color rgba="0.1 0.1 0.1 1"/>
    </material>
  </link>
  <joint name="bendy_joint_M7_SC0" type="revolute">
    <parent link="bendy_input_M7_SC0"/>
    <child link="bendy_output_M7_SC0"/>
    <origin rpy="0 0 0" xyz="-0.049 0 0"/>
    <axis xyz="0 1 0"/>
    <limit effort="100.0" lower="-1.57079632679" upper="1.57079632679" velocity="5"/>
  </joint>
  <link name="bendy_input_M8_S0C">
    <inertial>
      <origin rpy="0 0 0" xyz="-0.023 0 0"/>
      <mass value="0.13536"/>
      <inertia ixx="0.000047004" ixy="-0.000000049" ixz="0.000000017" iyy="0.000068413" iyz="0.000000009" izz="0.000070686"/>
    </inertial>
    <visual>
      <geometry>
        <mesh filename="package://eigenbot/meshes/Bendy In.STL" scale="1 1 1"/>
      </geometry>
    </visual>
    <collision>
      <geometry>
        <mesh filename="package://eigenbot/meshes/Bendy In.STL" scale="1 1 1"/>
      </geometry>
    </collision>
    <material name="black">
      <color rgba="0.1 0.1 0.1 1"/>
    </material>
  </link>
  <link name="bendy_output_M8_S0C">
    <inertial>
      <origin rpy="0 0 0" xyz="-0.029 0 0"/>
      <mass value=".03522"/>
      <inertia ixx="0.000021977" ixy="0.000000082" ixz="-0.000000063" iyy="0.000017473" iyz="0.000000067" izz="0.000021078"/>
    </inertial>
    <visual>
      <geometry>
        <mesh filename="package://eigenbot/meshes/Bendy Out.STL" scale="1 1 1"/>
      </geometry>
      <origin rpy="0 0 0" xyz="0 0 0 "/>
    </visual>
    <collision>
      <geometry>
        <mesh filename="package://eigenbot/meshes/Bendy Out.STL" scale="1 1 1"/>
      </geometry>
      <origin rpy="0 0 0" xyz="0 0 0"/>
    </collision>
    <material name="black">
      <color rgba="0.1 0.1 0.1 1"/>
    </material>
  </link>
  <joint name="bendy_joint_M8_S0C" type="revolute">
    <parent link="bendy_input_M8_S0C"/>
    <child link="bendy_output_M8_S0C"/>
    <origin rpy="0 0 0" xyz="-0.049 0 0"/>
    <axis xyz="0 1 0"/>
    <limit effort="100.0" lower="-1.57079632679" upper="1.57079632679" velocity="5"/>
  </joint>
  <link name="static_elbow_M9_SBB">
    <inertial>
      <origin rpy="0 0 0" xyz="-0.03148 0.00004 -0.01437"/>
      <mass value="0.06766"/>
      <inertia ixx="0.000052397" ixy="-0.0000001126" ixz="0.000015681" iyy="0.000065586" iyz="-0.000000082" izz="0.000053626"/>
    </inertial>
    <visual>
      <geometry>
        <mesh filename="package://eigenbot/meshes/Elbow.STL" scale="1 1 1"/>
      </geometry>
      <origin rpy="-1.57079632679 0 0" xyz="0 0 0"/>
    </visual>
    <collision>
      <geometry>
        <mesh filename="package://eigenbot/meshes/Elbow.STL" scale="1 1 1"/>
      </geometry>
      <origin rpy="-1.57079632679 0 0" xyz="0 0 0"/>
    </collision>
    <material name="black">
      <color rgba="0.1 0.1 0.1 1"/>
    </material>
  </link>
  <link name="foot_input_M10_S29">
    <inertial>
      <origin rpy="0 0 0" xyz="-0.03918 0 0"/>
      <mass value="0.04967"/>
      <inertia ixx="0.0000361" ixy="0" ixz="0" iyy="0.0000434" iyz="0" izz="0.0000434"/>
    </inertial>
    <visual>
      <geometry>
        <mesh filename="package://eigenbot/meshes/Foot.STL" scale=" 1 1 1 "/>
      </geometry>
    </visual>
    <collision>
      <geometry>
        <mesh filename="package://eigenbot/meshes/Foot.STL" scale=" 1 1 1 "/>
      </geometry>
    </collision>
    <material name="black">
      <color rgba="0.1 0.1 0.1 1"/>
    </material>
  </link>
  <link name="bendy_input_M11_S36">
    <inertial>
      <origin rpy="0 0 0" xyz="-0.023 0 0"/>
      <mass value="0.13536"/>
      <inertia ixx="0.000047004" ixy="-0.000000049" ixz="0.000000017" iyy="0.000068413" iyz="0.000000009" izz="0.000070686"/>
    </inertial>
    <visual>
      <geometry>
        <mesh filename="package://eigenbot/meshes/Bendy In.STL" scale="1 1 1"/>
      </geometry>
    </visual>
    <collision>
      <geometry>
        <mesh filename="package://eigenbot/meshes/Bendy In.STL" scale="1 1 1"/>
      </geometry>
    </collision>
    <material name="black">
      <color rgba="0.1 0.1 0.1 1"/>
    </material>
  </link>
  <link name="bendy_output_M11_S36">
    <inertial>
      <origin rpy="0 0 0" xyz="-0.029 0 0"/>
      <mass value=".03522"/>
      <inertia ixx="0.000021977" ixy="0.000000082" ixz="-0.000000063" iyy="0.000017473" iyz="0.000000067" izz="0.000021078"/>
    </inertial>
    <visual>
      <geometry>
        <mesh filename="package://eigenbot/meshes/Bendy Out.STL" scale="1 1 1"/>
      </geometry>
      <origin rpy="0 0 0" xyz="0 0 0 "/>
    </visual>
    <collision>
      <geometry>
        <mesh filename="package://eigenbot/meshes/Bendy Out.STL" scale="1 1 1"/>
      </geometry>
      <origin rpy="0 0 0" xyz="0 0 0"/>
    </collision>
    <material name="black">
      <color rgba="0.1 0.1 0.1 1"/>
    </material>
  </link>
  <joint name="bendy_joint_M11_S36" type="revolute">
    <parent link="bendy_input_M11_S36"/>
    <child link="bendy_output_M11_S36"/>
    <origin rpy="0 0 0" xyz="-0.049 0 0"/>
    <axis xyz="0 1 0"/>
    <limit effort="100.0" lower="-1.57079632679" upper="1.57079632679" velocity="5"/>
  </joint>
  <link name="gripper_M12_S14">
    <inertial>
      <!-- TODO: check this is the right offset from CAD -->
      <origin rpy="0 0 0" xyz="-0.0381  -0.0015  -0.0037"/>
      <mass value=".388326"/>
      <inertia ixx="0.0001432" ixy="-0.0000013" ixz="-0.000003" iyy="0.0003879" iyz="-0.0000059" izz="0.0004005"/>
    </inertial>
    <visual>
      <origin rpy="0 0 0" xyz="0 0 0"/>
      <geometry>
        <mesh filename="package://eigenbot/meshes/Gripper.STL" scale="1 1 1"/>
      </geometry>
    </visual>
    <collision>
      <origin rpy="0 0 0" xyz="0 0 0"/>
      <geometry>
        <mesh filename="package://eigenbot/meshes/Gripper.STL" scale="1 1 1"/>
      </geometry>
    </collision>
    <material name="black">
      <color rgba="0.1 0.1 0.1 1"/>
    </material>
  </link>
  <link name="gripper_virtual_M12_S14">
    <inertial>
      <origin rpy="0 0 0" xyz="0 0 0"/>
      <mass value=".01"/>
      <inertia ixx=".000001" ixy="0" ixz="0" iyy=".000001" iyz="0" izz=".000001"/>
    </inertial>
  </link>
  <joint name="gripper_joint_M12_S14" type="revolute">
    <parent link="gripper_M12_S14"/>
    <child link="gripper_virtual_M12_S14"/>
    <origin rpy="0 0 0" xyz="0 0 0"/>
    <axis xyz="0 1 0"/>
    <limit effort="1000.0" lower="0" upper="2.6" velocity="2"/>
  </joint>
  <link name="bendy_input_M13_SB9">
    <inertial>
      <origin rpy="0 0 0" xyz="-0.023 0 0"/>
      <mass value="0.13536"/>
      <inertia ixx="0.000047004" ixy="-0.000000049" ixz="0.000000017" iyy="0.000068413" iyz="0.000000009" izz="0.000070686"/>
    </inertial>
    <visual>
      <geometry>
        <mesh filename="package://eigenbot/meshes/Bendy In.STL" scale="1 1 1"/>
      </geometry>
    </visual>
    <collision>
      <geometry>
        <mesh filename="package://eigenbot/meshes/Bendy In.STL" scale="1 1 1"/>
      </geometry>
    </collision>
    <material name="black">
      <color rgba="0.1 0.1 0.1 1"/>
    </material>
  </link>
  <link name="bendy_output_M13_SB9">
    <inertial>
      <origin rpy="0 0 0" xyz="-0.029 0 0"/>
      <mass value=".03522"/>
      <inertia ixx="0.000021977" ixy="0.000000082" ixz="-0.000000063" iyy="0.000017473" iyz="0.000000067" izz="0.000021078"/>
    </inertial>
    <visual>
      <geometry>
        <mesh filename="package://eigenbot/meshes/Bendy Out.STL" scale="1 1 1"/>
      </geometry>
      <origin rpy="0 0 0" xyz="0 0 0 "/>
    </visual>
    <collision>
      <geometry>
        <mesh filename="package://eigenbot/meshes/Bendy Out.STL" scale="1 1 1"/>
      </geometry>
      <origin rpy="0 0 0" xyz="0 0 0"/>
    </collision>
    <material name="black">
      <color rgba="0.1 0.1 0.1 1"/>
    </material>
  </link>
  <joint name="bendy_joint_M13_SB9" type="revolute">
    <parent link="bendy_input_M13_SB9"/>
    <child link="bendy_output_M13_SB9"/>
    <origin rpy="0 0 0" xyz="-0.049 0 0"/>
    <axis xyz="0 1 0"/>
    <limit effort="100.0" lower="-1.57079632679" upper="1.57079632679" velocity="5"/>
  </joint>
  <link name="foot_input_M14_SC5">
    <inertial>
      <origin rpy="0 0 0" xyz="-0.03918 0 0"/>
      <mass value="0.04967"/>
      <inertia ixx="0.0000361" ixy="0" ixz="0" iyy="0.0000434" iyz="0" izz="0.0000434"/>
    </inertial>
    <visual>
      <geometry>
        <mesh filename="package://eigenbot/meshes/Foot.STL" scale=" 1 1 1 "/>
      </geometry>
    </visual>
    <collision>
      <geometry>
        <mesh filename="package://eigenbot/meshes/Foot.STL" scale=" 1 1 1 "/>
      </geometry>
    </collision>
    <material name="black">
      <color rgba="0.1 0.1 0.1 1"/>
    </material>
  </link>
  <link name="bendy_input_M15_S03">
    <inertial>
      <origin rpy="0 0 0" xyz="-0.023 0 0"/>
      <mass value="0.13536"/>
      <inertia ixx="0.000047004" ixy="-0.000000049" ixz="0.000000017" iyy="0.000068413" iyz="0.000000009" izz="0.000070686"/>
    </inertial>
    <visual>
      <geometry>
        <mesh filename="package://eigenbot/meshes/Bendy In.STL" scale="1 1 1"/>
      </geometry>
    </visual>
    <collision>
      <geometry>
        <mesh filename="package://eigenbot/meshes/Bendy In.STL" scale="1 1 1"/>
      </geometry>
    </collision>
    <material name="black">
      <color rgba="0.1 0.1 0.1 1"/>
    </material>
  </link>
  <link name="bendy_output_M15_S03">
    <inertial>
      <origin rpy="0 0 0" xyz="-0.029 0 0"/>
      <mass value=".03522"/>
      <inertia ixx="0.000021977" ixy="0.000000082" ixz="-0.000000063" iyy="0.000017473" iyz="0.000000067" izz="0.000021078"/>
    </inertial>
    <visual>
      <geometry>
        <mesh filename="package://eigenbot/meshes/Bendy Out.STL" scale="1 1 1"/>
      </geometry>
      <origin rpy="0 0 0" xyz="0 0 0 "/>
    </visual>
    <collision>
      <geometry>
        <mesh filename="package://eigenbot/meshes/Bendy Out.STL" scale="1 1 1"/>
      </geometry>
      <origin rpy="0 0 0" xyz="0 0 0"/>
    </collision>
    <material name="black">
      <color rgba="0.1 0.1 0.1 1"/>
    </material>
  </link>
  <joint name="bendy_joint_M15_S03" type="revolute">
    <parent link="bendy_input_M15_S03"/>
    <child link="bendy_output_M15_S03"/>
    <origin rpy="0 0 0" xyz="-0.049 0 0"/>
    <axis xyz="0 1 0"/>
    <limit effort="100.0" lower="-1.57079632679" upper="1.57079632679" velocity="5"/>
  </joint>
  <link name="static_elbow_M16_SB4">
    <inertial>
      <origin rpy="0 0 0" xyz="-0.03148 0.00004 -0.01437"/>
      <mass value="0.06766"/>
      <inertia ixx="0.000052397" ixy="-0.0000001126" ixz="0.000015681" iyy="0.000065586" iyz="-0.000000082" izz="0.000053626"/>
    </inertial>
    <visual>
      <geometry>
        <mesh filename="package://eigenbot/meshes/Elbow.STL" scale="1 1 1"/>
      </geometry>
      <origin rpy="-1.57079632679 0 0" xyz="0 0 0"/>
    </visual>
    <collision>
      <geometry>
        <mesh filename="package://eigenbot/meshes/Elbow.STL" scale="1 1 1"/>
      </geometry>
      <origin rpy="-1.57079632679 0 0" xyz="0 0 0"/>
    </collision>
    <material name="black">
      <color rgba="0.1 0.1 0.1 1"/>
    </material>
  </link>
  <link name="bendy_input_M17_S0A">
    <inertial>
      <origin rpy="0 0 0" xyz="-0.023 0 0"/>
      <mass value="0.13536"/>
      <inertia ixx="0.000047004" ixy="-0.000000049" ixz="0.000000017" iyy="0.000068413" iyz="0.000000009" izz="0.000070686"/>
    </inertial>
    <visual>
      <geometry>
        <mesh filename="package://eigenbot/meshes/Bendy In.STL" scale="1 1 1"/>
      </geometry>
    </visual>
    <collision>
      <geometry>
        <mesh filename="package://eigenbot/meshes/Bendy In.STL" scale="1 1 1"/>
      </geometry>
    </collision>
    <material name="black">
      <color rgba="0.1 0.1 0.1 1"/>
    </material>
  </link>
  <link name="bendy_output_M17_S0A">
    <inertial>
      <origin rpy="0 0 0" xyz="-0.029 0 0"/>
      <mass value=".03522"/>
      <inertia ixx="0.000021977" ixy="0.000000082" ixz="-0.000000063" iyy="0.000017473" iyz="0.000000067" izz="0.000021078"/>
    </inertial>
    <visual>
      <geometry>
        <mesh filename="package://eigenbot/meshes/Bendy Out.STL" scale="1 1 1"/>
      </geometry>
      <origin rpy="0 0 0" xyz="0 0 0 "/>
    </visual>
    <collision>
      <geometry>
        <mesh filename="package://eigenbot/meshes/Bendy Out.STL" scale="1 1 1"/>
      </geometry>
      <origin rpy="0 0 0" xyz="0 0 0"/>
    </collision>
    <material name="black">
      <color rgba="0.1 0.1 0.1 1"/>
    </material>
  </link>
  <joint name="bendy_joint_M17_S0A" type="revolute">
    <parent link="bendy_input_M17_S0A"/>
    <child link="bendy_output_M17_S0A"/>
    <origin rpy="0 0 0" xyz="-0.049 0 0"/>
    <axis xyz="0 1 0"/>
    <limit effort="100.0" lower="-1.57079632679" upper="1.57079632679" velocity="5"/>
  </joint>
  <link name="eigenbody_M18_S00">
    <inertial>
      <mass value="0.84845"/>
      <origin rpy="0 0 0" xyz="-0.045 0 -0.063"/>
      <inertia ixx=".005031284" ixy="0.000000338" ixz="0.000086805" iyy="0.003968526" iyz="0.000039596" izz="0.001646162"/>
    </inertial>
    <visual>
      <geometry>
        <mesh filename="package://eigenbot/meshes/Eigenbody.STL" scale="1 1 1"/>
      </geometry>
    </visual>
    <collision>
      <geometry>
        <mesh filename="package://eigenbot/meshes/Eigenbody.STL" scale="1 1 1"/>
      </geometry>
    </collision>
    <material name="black">
      <color rgba="0.1 0.1 0.1 1"/>
    </material>
  </link>
  <link name="bendy_input_M19_S5A">
    <inertial>
      <origin rpy="0 0 0" xyz="-0.023 0 0"/>
      <mass value="0.13536"/>
      <inertia ixx="0.000047004" ixy="-0.000000049" ixz="0.000000017" iyy="0.000068413" iyz="0.000000009" izz="0.000070686"/>
    </inertial>
    <visual>
      <geometry>
        <mesh filename="package://eigenbot/meshes/Bendy In.STL" scale="1 1 1"/>
      </geometry>
    </visual>
    <collision>
      <geometry>
        <mesh filename="package://eigenbot/meshes/Bendy In.STL" scale="1 1 1"/>
      </geometry>
    </collision>
    <material name="black">
      <color rgba="0.1 0.1 0.1 1"/>
    </material>
  </link>
  <link name="bendy_output_M19_S5A">
    <inertial>
      <origin rpy="0 0 0" xyz="-0.029 0 0"/>
      <mass value=".03522"/>
      <inertia ixx="0.000021977" ixy="0.000000082" ixz="-0.000000063" iyy="0.000017473" iyz="0.000000067" izz="0.000021078"/>
    </inertial>
    <visual>
      <geometry>
        <mesh filename="package://eigenbot/meshes/Bendy Out.STL" scale="1 1 1"/>
      </geometry>
      <origin rpy="0 0 0" xyz="0 0 0 "/>
    </visual>
    <collision>
      <geometry>
        <mesh filename="package://eigenbot/meshes/Bendy Out.STL" scale="1 1 1"/>
      </geometry>
      <origin rpy="0 0 0" xyz="0 0 0"/>
    </collision>
    <material name="black">
      <color rgba="0.1 0.1 0.1 1"/>
    </material>
  </link>
  <joint name="bendy_joint_M19_S5A" type="revolute">
    <parent link="bendy_input_M19_S5A"/>
    <child link="bendy_output_M19_S5A"/>
    <origin rpy="0 0 0" xyz="-0.049 0 0"/>
    <axis xyz="0 1 0"/>
    <limit effort="100.0" lower="-1.57079632679" upper="1.57079632679" velocity="5"/>
  </joint>
  <link name="bendy_input_M20_SE9">
    <inertial>
      <origin rpy="0 0 0" xyz="-0.023 0 0"/>
      <mass value="0.13536"/>
      <inertia ixx="0.000047004" ixy="-0.000000049" ixz="0.000000017" iyy="0.000068413" iyz="0.000000009" izz="0.000070686"/>
    </inertial>
    <visual>
      <geometry>
        <mesh filename="package://eigenbot/meshes/Bendy In.STL" scale="1 1 1"/>
      </geometry>
    </visual>
    <collision>
      <geometry>
        <mesh filename="package://eigenbot/meshes/Bendy In.STL" scale="1 1 1"/>
      </geometry>
    </collision>
    <material name="black">
      <color rgba="0.1 0.1 0.1 1"/>
    </material>
  </link>
  <link name="bendy_output_M20_SE9">
    <inertial>
      <origin rpy="0 0 0" xyz="-0.029 0 0"/>
      <mass value=".03522"/>
      <inertia ixx="0.000021977" ixy="0.000000082" ixz="-0.000000063" iyy="0.000017473" iyz="0.000000067" izz="0.000021078"/>
    </inertial>
    <visual>
      <geometry>
        <mesh filename="package://eigenbot/meshes/Bendy Out.STL" scale="1 1 1"/>
      </geometry>
      <origin rpy="0 0 0" xyz="0 0 0 "/>
    </visual>
    <collision>
      <geometry>
        <mesh filename="package://eigenbot/meshes/Bendy Out.STL" scale="1 1 1"/>
      </geometry>
      <origin rpy="0 0 0" xyz="0 0 0"/>
    </collision>
    <material name="black">
      <color rgba="0.1 0.1 0.1 1"/>
    </material>
  </link>
  <joint name="bendy_joint_M20_SE9" type="revolute">
    <parent link="bendy_input_M20_SE9"/>
    <child link="bendy_output_M20_SE9"/>
    <origin rpy="0 0 0" xyz="-0.049 0 0"/>
    <axis xyz="0 1 0"/>
    <limit effort="100.0" lower="-1.57079632679" upper="1.57079632679" velocity="5"/>
  </joint>
  <link name="static_elbow_M21_SC7">
    <inertial>
      <origin rpy="0 0 0" xyz="-0.03148 0.00004 -0.01437"/>
      <mass value="0.06766"/>
      <inertia ixx="0.000052397" ixy="-0.0000001126" ixz="0.000015681" iyy="0.000065586" iyz="-0.000000082" izz="0.000053626"/>
    </inertial>
    <visual>
      <geometry>
        <mesh filename="package://eigenbot/meshes/Elbow.STL" scale="1 1 1"/>
      </geometry>
      <origin rpy="-1.57079632679 0 0" xyz="0 0 0"/>
    </visual>
    <collision>
      <geometry>
        <mesh filename="package://eigenbot/meshes/Elbow.STL" scale="1 1 1"/>
      </geometry>
      <origin rpy="-1.57079632679 0 0" xyz="0 0 0"/>
    </collision>
    <material name="black">
      <color rgba="0.1 0.1 0.1 1"/>
    </material>
  </link>
  <link name="foot_input_M22_SB6">
    <inertial>
      <origin rpy="0 0 0" xyz="-0.03918 0 0"/>
      <mass value="0.04967"/>
      <inertia ixx="0.0000361" ixy="0" ixz="0" iyy="0.0000434" iyz="0" izz="0.0000434"/>
    </inertial>
    <visual>
      <geometry>
        <mesh filename="package://eigenbot/meshes/Foot.STL" scale=" 1 1 1 "/>
      </geometry>
    </visual>
    <collision>
      <geometry>
        <mesh filename="package://eigenbot/meshes/Foot.STL" scale=" 1 1 1 "/>
      </geometry>
    </collision>
    <material name="black">
      <color rgba="0.1 0.1 0.1 1"/>
    </material>
  </link>
  <link name="bendy_input_M23_S01">
    <inertial>
      <origin rpy="0 0 0" xyz="-0.023 0 0"/>
      <mass value="0.13536"/>
      <inertia ixx="0.000047004" ixy="-0.000000049" ixz="0.000000017" iyy="0.000068413" iyz="0.000000009" izz="0.000070686"/>
    </inertial>
    <visual>
      <geometry>
        <mesh filename="package://eigenbot/meshes/Bendy In.STL" scale="1 1 1"/>
      </geometry>
    </visual>
    <collision>
      <geometry>
        <mesh filename="package://eigenbot/meshes/Bendy In.STL" scale="1 1 1"/>
      </geometry>
    </collision>
    <material name="black">
      <color rgba="0.1 0.1 0.1 1"/>
    </material>
  </link>
  <link name="bendy_output_M23_S01">
    <inertial>
      <origin rpy="0 0 0" xyz="-0.029 0 0"/>
      <mass value=".03522"/>
      <inertia ixx="0.000021977" ixy="0.000000082" ixz="-0.000000063" iyy="0.000017473" iyz="0.000000067" izz="0.000021078"/>
    </inertial>
    <visual>
      <geometry>
        <mesh filename="package://eigenbot/meshes/Bendy Out.STL" scale="1 1 1"/>
      </geometry>
      <origin rpy="0 0 0" xyz="0 0 0 "/>
    </visual>
    <collision>
      <geometry>
        <mesh filename="package://eigenbot/meshes/Bendy Out.STL" scale="1 1 1"/>
      </geometry>
      <origin rpy="0 0 0" xyz="0 0 0"/>
    </collision>
    <material name="black">
      <color rgba="0.1 0.1 0.1 1"/>
    </material>
  </link>
  <joint name="bendy_joint_M23_S01" type="revolute">
    <parent link="bendy_input_M23_S01"/>
    <child link="bendy_output_M23_S01"/>
    <origin rpy="0 0 0" xyz="-0.049 0 0"/>
    <axis xyz="0 1 0"/>
    <limit effort="100.0" lower="-1.57079632679" upper="1.57079632679" velocity="5"/>
  </joint>
  <joint name="connection_0_attachment" type="fixed">
    <origin rpy="4.71238898038 0 0" xyz="-0.036 0 0"/>
    <parent link="bendy_output_M3_S02"/>
    <child link="bendy_input_M5_S1D"/>
  </joint>
  <joint name="connection_1_attachment" type="fixed">
    <origin rpy="4.71238898038 0 1.57079632679" xyz="-0.0455 -0.0375 0"/>
    <parent link="static_elbow_M4_S42"/>
    <child link="bendy_input_M6_S53"/>
  </joint>
  <joint name="connection_2_attachment" type="fixed">
    <origin rpy="1.57079632679 0 0" xyz="-0.036 0 0"/>
    <parent link="bendy_output_M5_S1D"/>
    <child link="static_elbow_M4_S42"/>
  </joint>
  <joint name="connection_3_attachment" type="fixed">
    <origin rpy="3.14159265359 0 0" xyz="-0.036 0 0"/>
    <parent link="bendy_output_M6_S53"/>
    <child link="foot_input_M2_S47"/>
  </joint>
  <joint name="connection_4_attachment" type="fixed">
    <origin rpy="4.71238898038 0 0" xyz="-0.036 0 0"/>
    <parent link="bendy_output_M7_SC0"/>
    <child link="bendy_input_M8_S0C"/>
  </joint>
  <joint name="connection_5_attachment" type="fixed">
    <origin rpy="1.57079632679 0 0" xyz="-0.036 0 0"/>
    <parent link="bendy_output_M8_S0C"/>
    <child link="static_elbow_M9_SBB"/>
  </joint>
  <joint name="connection_6_attachment" type="fixed">
    <origin rpy="1.57079632679 0 1.57079632679" xyz="-0.0455 -0.0375 0"/>
    <parent link="static_elbow_M9_SBB"/>
    <child link="bendy_input_M11_S36"/>
  </joint>
  <joint name="connection_7_attachment" type="fixed">
    <origin rpy="3.14159265359 0 0" xyz="-0.036 0 0"/>
    <parent link="bendy_output_M11_S36"/>
    <child link="foot_input_M10_S29"/>
  </joint>
  <joint name="connection_8_attachment" type="fixed">
    <origin rpy="4.71238898038 0 0" xyz="-0.036 0 0"/>
    <parent link="bendy_output_M13_SB9"/>
    <child link="bendy_input_M15_S03"/>
  </joint>
  <joint name="connection_9_attachment" type="fixed">
    <origin rpy="1.57079632679 0 0" xyz="-0.036 0 0"/>
    <parent link="bendy_output_M15_S03"/>
    <child link="static_elbow_M16_SB4"/>
  </joint>
  <joint name="connection_10_attachment" type="fixed">
    <origin rpy="4.71238898038 0 1.57079632679" xyz="-0.0455 -0.0375 0"/>
    <parent link="static_elbow_M16_SB4"/>
    <child link="bendy_input_M17_S0A"/>
  </joint>
  <joint name="connection_11_attachment" type="fixed">
    <origin rpy="3.14159265359 0 0" xyz="-0.036 0 0"/>
    <parent link="bendy_output_M17_S0A"/>
    <child link="foot_input_M14_SC5"/>
  </joint>
  <joint name="connection_12_attachment" type="fixed">
    <origin rpy="0 0 -1.57079632679" xyz="-0.041 0.067 -0.13"/>
    <parent link="eigenbody_M18_S00"/>
    <child link="bendy_input_M3_S02"/>
  </joint>
  <joint name="connection_13_attachment" type="fixed">
    <origin rpy="0 0 -1.57079632679" xyz="-0.041 0.067 -0.04"/>
    <parent link="eigenbody_M18_S00"/>
    <child link="bendy_input_M19_S5A"/>
  </joint>
  <joint name="connection_14_attachment" type="fixed">
    <origin rpy="0.785398163397 0 -1.57079632679" xyz="-0.041 0.067 0.05"/>
    <parent link="eigenbody_M18_S00"/>
    <child link="wheel_input_M0_SF1"/>
  </joint>
  <joint name="connection_15_attachment" type="fixed">
    <origin rpy="8.63937979737 0 1.57079632679" xyz="-0.041 -0.067 0.05"/>
    <parent link="eigenbody_M18_S00"/>
    <child link="wheel_input_M1_SF3"/>
  </joint>
  <joint name="connection_16_attachment" type="fixed">
    <origin rpy="3.14159265359 0 1.57079632679" xyz="-0.041 -0.067 -0.04"/>
    <parent link="eigenbody_M18_S00"/>
    <child link="bendy_input_M13_SB9"/>
  </joint>
  <joint name="connection_17_attachment" type="fixed">
    <origin rpy="3.14159265359 0 1.57079632679" xyz="-0.041 -0.067 -0.13"/>
    <parent link="eigenbody_M18_S00"/>
    <child link="bendy_input_M7_SC0"/>
  </joint>
  <joint name="connection_18_attachment" type="fixed">
    <origin rpy="0 0 3.14159265359" xyz="-0.009 0 -0.08"/>
    <parent link="eigenbody_M18_S00"/>
    <child link="gripper_M12_S14"/>
  </joint>
  <joint name="connection_19_attachment" type="fixed">
    <origin rpy="4.71238898038 0 0" xyz="-0.036 0 0"/>
    <parent link="bendy_output_M19_S5A"/>
    <child link="bendy_input_M20_SE9"/>
  </joint>
  <joint name="connection_20_attachment" type="fixed">
    <origin rpy="1.57079632679 0 0" xyz="-0.036 0 0"/>
    <parent link="bendy_output_M20_SE9"/>
    <child link="static_elbow_M21_SC7"/>
  </joint>
  <joint name="connection_21_attachment" type="fixed">
    <origin rpy="4.71238898038 0 1.57079632679" xyz="-0.0455 -0.0375 0"/>
    <parent link="static_elbow_M21_SC7"/>
    <child link="bendy_input_M23_S01"/>
  </joint>
  <joint name="connection_22_attachment" type="fixed">
    <origin rpy="3.14159265359 0 0" xyz="-0.036 0 0"/>
    <parent link="bendy_output_M23_S01"/>
    <child link="foot_input_M22_SB6"/>
  </joint>
</robot>
