<?xml version="1.0"?>
<robot xmlns:xacro="http://www.ros.org/wiki/xacro">
  <xacro:macro name="hebi_x5_9" params="module_label">
  <xacro:property name="model_name" value="X5_9"/>

    <link name="hebi_x5_9_input_${module_label}">
      <visual>
        <origin xyz="0 0 0" rpy="0 0 0" />
        <geometry>
          <mesh filename="package://eigenbot/meshes/x5.stl" scale="0.001 0.001 0.001"/>
        </geometry>
      </visual>
      <collision>
        <origin xyz="0 0 0" rpy="0 0 0" />
        <geometry>
          <mesh filename="package://eigenbot/meshes/x5.stl" scale="0.001 0.001 0.001"/>
        </geometry>
      </collision>
      <inertial>
        <origin xyz="-0.0142 -0.0031 0.0165" rpy="0 0 0" />
        <xacro:if value="${model_name == 'X5_1'}">
          <mass value="0.315"/>
        </xacro:if>
        <xacro:if value="${model_name == 'X5_4'}">
          <mass value="0.335"/>
        </xacro:if>
        <xacro:if value="${model_name == 'X5_9'}">
          <mass value="0.360"/>
        </xacro:if>
        <inertia ixx="0.00015" iyy="0.000255" izz="0.000350" ixy="0.0000341" ixz="0.0000118" iyz="0.00000229"/>
      </inertial>
    </link>


    <!-- invisible internal joint which the next module can attach to . Give it a small mass to avoid infinite speed rotations.-->
   <link name="hebi_x5_9_output_${module_label}">
      <inertial>
        <origin xyz="0 0 0" rpy="0 0 0" />
            <mass value="0.001"/>
        <inertia ixx="0.000001" iyy="0.000001" izz="0.000001" ixy="0" ixz="0" iyz="0"/>
      </inertial>
    </link>


    <xacro:if value="${model_name == 'X5_1'}">
      <joint name="$hebi_x5_9_joint_${module_label}" type="continuous">
        <parent link="hebi_x5_9_input_${module_label}"/>
        <child link="hebi_x5_9_output_${module_label}"/>
        <origin xyz="0 0 0.031" rpy="0 0 0"/>
        <axis xyz="0 0 1"/>
        <limit effort="2.5" velocity="90"/>
        <dynamics damping="0.1" friction="0.1"/>
      </joint>
    </xacro:if>
    <xacro:if value="${model_name == 'X5_4'}">
      <joint name="hebi_x5_9_joint_${module_label}" type="continuous">
        <parent link="hebi_x5_9_input_${module_label}"/>
        <child link="hebi_x5_9_output_${module_label}"/>
        <origin xyz="0 0 0.031" rpy="0 0 0"/>
        <axis xyz="0 0 1"/>
        <limit effort="7.0" velocity="32"/>
        <dynamics damping="0.1" friction="0.1"/>
      </joint>
    </xacro:if>
    <xacro:if value="${model_name == 'X5_9'}">
      <joint name="hebi_x5_9_joint_${module_label}" type="continuous">
        <parent link="hebi_x5_9_input_${module_label}"/>
        <child link="hebi_x5_9_output_${module_label}"/>
        <origin xyz="0 0 0.031" rpy="0 0 0"/>
        <axis xyz="0 0 1"/>
        <limit effort="13.0" velocity="14"/>
        <dynamics damping="0.1" friction="0.1"/>
      </joint>
    </xacro:if>

    <gazebo reference="$hebi_x5_9_input_${module_label}">
      <selfCollide>true</selfCollide>
      <gravity>true</gravity>
      <sensor name="hebi_x5_9_joint_${module_label}/imu_sensor" type="imu">
        <always_on>true</always_on>
        <update_rate>100</update_rate>
        <visualize>true</visualize>
        <plugin filename="libgazebo_ros_imu_sensor.so" name="imu_plugin">
          <topicName>/hebiros_gazebo_plugin/imu/hebi_x5_9_joint_${module_label}</topicName>
          <bodyName>hebi_x5_9_joint_${module_label}/imu_link</bodyName>
          <updateRateHZ>10.0</updateRateHZ>
          <gaussianNoise>0.0</gaussianNoise>
          <xyzOffset>0.025 0 0.003</xyzOffset>
          <rpyOffset>0 0 0</rpyOffset>
          <frameName>hebi_x5_9_joint_${module_label}/imu_link</frameName>
        </plugin>
        <pose>0 0 0 0 0 0</pose>
      </sensor>
    </gazebo>

  </xacro:macro>
</robot>

