<?xml version="1.0" ?>
<!-- =================================================================================== -->
<!-- |    This document was autogenerated by xacro from /home/cobracommander/catkin_ws/src/eigenbot/urdf/autoXACRO.xacro | -->
<!-- |    EDITING THIS FILE BY HAND IS NOT RECOMMENDED                                 | -->
<!-- =================================================================================== -->
<robot name="modular_robot_compiled" xmlns:xacro="http://www.ros.org/wiki/xacro">
  <link name="eigenbody_M0_S0">
    <inertial>
      <mass value="0.84845"/>
      <origin rpy="0 0 0" xyz="-0.045 0 -0.063"/>
      <inertia ixx=".005031284" ixy="0.000000338" ixz="0.000086805" iyy="0.003968526" iyz="0.000039596" izz="0.001646162"/>
    </inertial>
    <visual>
      <geometry>
        <mesh filename="package://eigenbot/meshes/Eigenbody.STL" scale="1 1 1"/>
      </geometry>
    </visual>
    <collision>
      <geometry>
        <mesh filename="package://eigenbot/meshes/Eigenbody.STL" scale="1 1 1"/>
      </geometry>
    </collision>
    <material name="black">
      <color rgba="0.1 0.1 0.1 1"/>
    </material>
  </link>
  <link name="bendy_input_M1_S1">
    <inertial>
      <origin rpy="0 0 0" xyz="-0.023 0 0"/>
      <mass value="0.13536"/>
      <inertia ixx="0.000047004" ixy="-0.000000049" ixz="0.000000017" iyy="0.000068413" iyz="0.000000009" izz="0.000070686"/>
    </inertial>
    <visual>
      <geometry>
        <mesh filename="package://eigenbot/meshes/Bendy In.STL" scale="1 1 1"/>
      </geometry>
    </visual>
    <collision>
      <geometry>
        <mesh filename="package://eigenbot/meshes/Bendy In.STL" scale="1 1 1"/>
      </geometry>
    </collision>
    <material name="black">
      <color rgba="0.1 0.1 0.1 1"/>
    </material>
  </link>
  <link name="bendy_output_M1_S1">
    <inertial>
      <origin rpy="0 0 0" xyz="-0.029 0 0"/>
      <mass value=".03522"/>
      <inertia ixx="0.000021977" ixy="0.000000082" ixz="-0.000000063" iyy="0.000017473" iyz="0.000000067" izz="0.000021078"/>
    </inertial>
    <visual>
      <geometry>
        <mesh filename="package://eigenbot/meshes/Bendy Out.STL" scale="1 1 1"/>
      </geometry>
      <origin rpy="0 0 0" xyz="0 0 0 "/>
    </visual>
    <collision>
      <geometry>
        <mesh filename="package://eigenbot/meshes/Bendy Out.STL" scale="1 1 1"/>
      </geometry>
      <origin rpy="0 0 0" xyz="0 0 0"/>
    </collision>
    <material name="black">
      <color rgba="0.1 0.1 0.1 1"/>
    </material>
  </link>
  <joint name="bendy_joint_M1_S1" type="revolute">
    <parent link="bendy_input_M1_S1"/>
    <child link="bendy_output_M1_S1"/>
    <origin rpy="0 0 0" xyz="-0.049 0 0"/>
    <axis xyz="0 1 0"/>
    <limit effort="100.0" lower="-1.57079632679" upper="1.57079632679" velocity="5"/>
  </joint>
  <link name="bendy_input_M2_S2">
    <inertial>
      <origin rpy="0 0 0" xyz="-0.023 0 0"/>
      <mass value="0.13536"/>
      <inertia ixx="0.000047004" ixy="-0.000000049" ixz="0.000000017" iyy="0.000068413" iyz="0.000000009" izz="0.000070686"/>
    </inertial>
    <visual>
      <geometry>
        <mesh filename="package://eigenbot/meshes/Bendy In.STL" scale="1 1 1"/>
      </geometry>
    </visual>
    <collision>
      <geometry>
        <mesh filename="package://eigenbot/meshes/Bendy In.STL" scale="1 1 1"/>
      </geometry>
    </collision>
    <material name="black">
      <color rgba="0.1 0.1 0.1 1"/>
    </material>
  </link>
  <link name="bendy_output_M2_S2">
    <inertial>
      <origin rpy="0 0 0" xyz="-0.029 0 0"/>
      <mass value=".03522"/>
      <inertia ixx="0.000021977" ixy="0.000000082" ixz="-0.000000063" iyy="0.000017473" iyz="0.000000067" izz="0.000021078"/>
    </inertial>
    <visual>
      <geometry>
        <mesh filename="package://eigenbot/meshes/Bendy Out.STL" scale="1 1 1"/>
      </geometry>
      <origin rpy="0 0 0" xyz="0 0 0 "/>
    </visual>
    <collision>
      <geometry>
        <mesh filename="package://eigenbot/meshes/Bendy Out.STL" scale="1 1 1"/>
      </geometry>
      <origin rpy="0 0 0" xyz="0 0 0"/>
    </collision>
    <material name="black">
      <color rgba="0.1 0.1 0.1 1"/>
    </material>
  </link>
  <joint name="bendy_joint_M2_S2" type="revolute">
    <parent link="bendy_input_M2_S2"/>
    <child link="bendy_output_M2_S2"/>
    <origin rpy="0 0 0" xyz="-0.049 0 0"/>
    <axis xyz="0 1 0"/>
    <limit effort="100.0" lower="-1.57079632679" upper="1.57079632679" velocity="5"/>
  </joint>
  <link name="bendy_input_M3_S3">
    <inertial>
      <origin rpy="0 0 0" xyz="-0.023 0 0"/>
      <mass value="0.13536"/>
      <inertia ixx="0.000047004" ixy="-0.000000049" ixz="0.000000017" iyy="0.000068413" iyz="0.000000009" izz="0.000070686"/>
    </inertial>
    <visual>
      <geometry>
        <mesh filename="package://eigenbot/meshes/Bendy In.STL" scale="1 1 1"/>
      </geometry>
    </visual>
    <collision>
      <geometry>
        <mesh filename="package://eigenbot/meshes/Bendy In.STL" scale="1 1 1"/>
      </geometry>
    </collision>
    <material name="black">
      <color rgba="0.1 0.1 0.1 1"/>
    </material>
  </link>
  <link name="bendy_output_M3_S3">
    <inertial>
      <origin rpy="0 0 0" xyz="-0.029 0 0"/>
      <mass value=".03522"/>
      <inertia ixx="0.000021977" ixy="0.000000082" ixz="-0.000000063" iyy="0.000017473" iyz="0.000000067" izz="0.000021078"/>
    </inertial>
    <visual>
      <geometry>
        <mesh filename="package://eigenbot/meshes/Bendy Out.STL" scale="1 1 1"/>
      </geometry>
      <origin rpy="0 0 0" xyz="0 0 0 "/>
    </visual>
    <collision>
      <geometry>
        <mesh filename="package://eigenbot/meshes/Bendy Out.STL" scale="1 1 1"/>
      </geometry>
      <origin rpy="0 0 0" xyz="0 0 0"/>
    </collision>
    <material name="black">
      <color rgba="0.1 0.1 0.1 1"/>
    </material>
  </link>
  <joint name="bendy_joint_M3_S3" type="revolute">
    <parent link="bendy_input_M3_S3"/>
    <child link="bendy_output_M3_S3"/>
    <origin rpy="0 0 0" xyz="-0.049 0 0"/>
    <axis xyz="0 1 0"/>
    <limit effort="100.0" lower="-1.57079632679" upper="1.57079632679" velocity="5"/>
  </joint>
  <link name="bendy_input_M4_S4">
    <inertial>
      <origin rpy="0 0 0" xyz="-0.023 0 0"/>
      <mass value="0.13536"/>
      <inertia ixx="0.000047004" ixy="-0.000000049" ixz="0.000000017" iyy="0.000068413" iyz="0.000000009" izz="0.000070686"/>
    </inertial>
    <visual>
      <geometry>
        <mesh filename="package://eigenbot/meshes/Bendy In.STL" scale="1 1 1"/>
      </geometry>
    </visual>
    <collision>
      <geometry>
        <mesh filename="package://eigenbot/meshes/Bendy In.STL" scale="1 1 1"/>
      </geometry>
    </collision>
    <material name="black">
      <color rgba="0.1 0.1 0.1 1"/>
    </material>
  </link>
  <link name="bendy_output_M4_S4">
    <inertial>
      <origin rpy="0 0 0" xyz="-0.029 0 0"/>
      <mass value=".03522"/>
      <inertia ixx="0.000021977" ixy="0.000000082" ixz="-0.000000063" iyy="0.000017473" iyz="0.000000067" izz="0.000021078"/>
    </inertial>
    <visual>
      <geometry>
        <mesh filename="package://eigenbot/meshes/Bendy Out.STL" scale="1 1 1"/>
      </geometry>
      <origin rpy="0 0 0" xyz="0 0 0 "/>
    </visual>
    <collision>
      <geometry>
        <mesh filename="package://eigenbot/meshes/Bendy Out.STL" scale="1 1 1"/>
      </geometry>
      <origin rpy="0 0 0" xyz="0 0 0"/>
    </collision>
    <material name="black">
      <color rgba="0.1 0.1 0.1 1"/>
    </material>
  </link>
  <joint name="bendy_joint_M4_S4" type="revolute">
    <parent link="bendy_input_M4_S4"/>
    <child link="bendy_output_M4_S4"/>
    <origin rpy="0 0 0" xyz="-0.049 0 0"/>
    <axis xyz="0 1 0"/>
    <limit effort="100.0" lower="-1.57079632679" upper="1.57079632679" velocity="5"/>
  </joint>
  <link name="bendy_input_M5_S5">
    <inertial>
      <origin rpy="0 0 0" xyz="-0.023 0 0"/>
      <mass value="0.13536"/>
      <inertia ixx="0.000047004" ixy="-0.000000049" ixz="0.000000017" iyy="0.000068413" iyz="0.000000009" izz="0.000070686"/>
    </inertial>
    <visual>
      <geometry>
        <mesh filename="package://eigenbot/meshes/Bendy In.STL" scale="1 1 1"/>
      </geometry>
    </visual>
    <collision>
      <geometry>
        <mesh filename="package://eigenbot/meshes/Bendy In.STL" scale="1 1 1"/>
      </geometry>
    </collision>
    <material name="black">
      <color rgba="0.1 0.1 0.1 1"/>
    </material>
  </link>
  <link name="bendy_output_M5_S5">
    <inertial>
      <origin rpy="0 0 0" xyz="-0.029 0 0"/>
      <mass value=".03522"/>
      <inertia ixx="0.000021977" ixy="0.000000082" ixz="-0.000000063" iyy="0.000017473" iyz="0.000000067" izz="0.000021078"/>
    </inertial>
    <visual>
      <geometry>
        <mesh filename="package://eigenbot/meshes/Bendy Out.STL" scale="1 1 1"/>
      </geometry>
      <origin rpy="0 0 0" xyz="0 0 0 "/>
    </visual>
    <collision>
      <geometry>
        <mesh filename="package://eigenbot/meshes/Bendy Out.STL" scale="1 1 1"/>
      </geometry>
      <origin rpy="0 0 0" xyz="0 0 0"/>
    </collision>
    <material name="black">
      <color rgba="0.1 0.1 0.1 1"/>
    </material>
  </link>
  <joint name="bendy_joint_M5_S5" type="revolute">
    <parent link="bendy_input_M5_S5"/>
    <child link="bendy_output_M5_S5"/>
    <origin rpy="0 0 0" xyz="-0.049 0 0"/>
    <axis xyz="0 1 0"/>
    <limit effort="100.0" lower="-1.57079632679" upper="1.57079632679" velocity="5"/>
  </joint>
  <link name="bendy_input_M6_S6">
    <inertial>
      <origin rpy="0 0 0" xyz="-0.023 0 0"/>
      <mass value="0.13536"/>
      <inertia ixx="0.000047004" ixy="-0.000000049" ixz="0.000000017" iyy="0.000068413" iyz="0.000000009" izz="0.000070686"/>
    </inertial>
    <visual>
      <geometry>
        <mesh filename="package://eigenbot/meshes/Bendy In.STL" scale="1 1 1"/>
      </geometry>
    </visual>
    <collision>
      <geometry>
        <mesh filename="package://eigenbot/meshes/Bendy In.STL" scale="1 1 1"/>
      </geometry>
    </collision>
    <material name="black">
      <color rgba="0.1 0.1 0.1 1"/>
    </material>
  </link>
  <link name="bendy_output_M6_S6">
    <inertial>
      <origin rpy="0 0 0" xyz="-0.029 0 0"/>
      <mass value=".03522"/>
      <inertia ixx="0.000021977" ixy="0.000000082" ixz="-0.000000063" iyy="0.000017473" iyz="0.000000067" izz="0.000021078"/>
    </inertial>
    <visual>
      <geometry>
        <mesh filename="package://eigenbot/meshes/Bendy Out.STL" scale="1 1 1"/>
      </geometry>
      <origin rpy="0 0 0" xyz="0 0 0 "/>
    </visual>
    <collision>
      <geometry>
        <mesh filename="package://eigenbot/meshes/Bendy Out.STL" scale="1 1 1"/>
      </geometry>
      <origin rpy="0 0 0" xyz="0 0 0"/>
    </collision>
    <material name="black">
      <color rgba="0.1 0.1 0.1 1"/>
    </material>
  </link>
  <joint name="bendy_joint_M6_S6" type="revolute">
    <parent link="bendy_input_M6_S6"/>
    <child link="bendy_output_M6_S6"/>
    <origin rpy="0 0 0" xyz="-0.049 0 0"/>
    <axis xyz="0 1 0"/>
    <limit effort="100.0" lower="-1.57079632679" upper="1.57079632679" velocity="5"/>
  </joint>
  <link name="bendy_input_M7_S7">
    <inertial>
      <origin rpy="0 0 0" xyz="-0.023 0 0"/>
      <mass value="0.13536"/>
      <inertia ixx="0.000047004" ixy="-0.000000049" ixz="0.000000017" iyy="0.000068413" iyz="0.000000009" izz="0.000070686"/>
    </inertial>
    <visual>
      <geometry>
        <mesh filename="package://eigenbot/meshes/Bendy In.STL" scale="1 1 1"/>
      </geometry>
    </visual>
    <collision>
      <geometry>
        <mesh filename="package://eigenbot/meshes/Bendy In.STL" scale="1 1 1"/>
      </geometry>
    </collision>
    <material name="black">
      <color rgba="0.1 0.1 0.1 1"/>
    </material>
  </link>
  <link name="bendy_output_M7_S7">
    <inertial>
      <origin rpy="0 0 0" xyz="-0.029 0 0"/>
      <mass value=".03522"/>
      <inertia ixx="0.000021977" ixy="0.000000082" ixz="-0.000000063" iyy="0.000017473" iyz="0.000000067" izz="0.000021078"/>
    </inertial>
    <visual>
      <geometry>
        <mesh filename="package://eigenbot/meshes/Bendy Out.STL" scale="1 1 1"/>
      </geometry>
      <origin rpy="0 0 0" xyz="0 0 0 "/>
    </visual>
    <collision>
      <geometry>
        <mesh filename="package://eigenbot/meshes/Bendy Out.STL" scale="1 1 1"/>
      </geometry>
      <origin rpy="0 0 0" xyz="0 0 0"/>
    </collision>
    <material name="black">
      <color rgba="0.1 0.1 0.1 1"/>
    </material>
  </link>
  <joint name="bendy_joint_M7_S7" type="revolute">
    <parent link="bendy_input_M7_S7"/>
    <child link="bendy_output_M7_S7"/>
    <origin rpy="0 0 0" xyz="-0.049 0 0"/>
    <axis xyz="0 1 0"/>
    <limit effort="100.0" lower="-1.57079632679" upper="1.57079632679" velocity="5"/>
  </joint>
  <link name="bendy_input_M8_S8">
    <inertial>
      <origin rpy="0 0 0" xyz="-0.023 0 0"/>
      <mass value="0.13536"/>
      <inertia ixx="0.000047004" ixy="-0.000000049" ixz="0.000000017" iyy="0.000068413" iyz="0.000000009" izz="0.000070686"/>
    </inertial>
    <visual>
      <geometry>
        <mesh filename="package://eigenbot/meshes/Bendy In.STL" scale="1 1 1"/>
      </geometry>
    </visual>
    <collision>
      <geometry>
        <mesh filename="package://eigenbot/meshes/Bendy In.STL" scale="1 1 1"/>
      </geometry>
    </collision>
    <material name="black">
      <color rgba="0.1 0.1 0.1 1"/>
    </material>
  </link>
  <link name="bendy_output_M8_S8">
    <inertial>
      <origin rpy="0 0 0" xyz="-0.029 0 0"/>
      <mass value=".03522"/>
      <inertia ixx="0.000021977" ixy="0.000000082" ixz="-0.000000063" iyy="0.000017473" iyz="0.000000067" izz="0.000021078"/>
    </inertial>
    <visual>
      <geometry>
        <mesh filename="package://eigenbot/meshes/Bendy Out.STL" scale="1 1 1"/>
      </geometry>
      <origin rpy="0 0 0" xyz="0 0 0 "/>
    </visual>
    <collision>
      <geometry>
        <mesh filename="package://eigenbot/meshes/Bendy Out.STL" scale="1 1 1"/>
      </geometry>
      <origin rpy="0 0 0" xyz="0 0 0"/>
    </collision>
    <material name="black">
      <color rgba="0.1 0.1 0.1 1"/>
    </material>
  </link>
  <joint name="bendy_joint_M8_S8" type="revolute">
    <parent link="bendy_input_M8_S8"/>
    <child link="bendy_output_M8_S8"/>
    <origin rpy="0 0 0" xyz="-0.049 0 0"/>
    <axis xyz="0 1 0"/>
    <limit effort="100.0" lower="-1.57079632679" upper="1.57079632679" velocity="5"/>
  </joint>
  <link name="bendy_input_M9_S9">
    <inertial>
      <origin rpy="0 0 0" xyz="-0.023 0 0"/>
      <mass value="0.13536"/>
      <inertia ixx="0.000047004" ixy="-0.000000049" ixz="0.000000017" iyy="0.000068413" iyz="0.000000009" izz="0.000070686"/>
    </inertial>
    <visual>
      <geometry>
        <mesh filename="package://eigenbot/meshes/Bendy In.STL" scale="1 1 1"/>
      </geometry>
    </visual>
    <collision>
      <geometry>
        <mesh filename="package://eigenbot/meshes/Bendy In.STL" scale="1 1 1"/>
      </geometry>
    </collision>
    <material name="black">
      <color rgba="0.1 0.1 0.1 1"/>
    </material>
  </link>
  <link name="bendy_output_M9_S9">
    <inertial>
      <origin rpy="0 0 0" xyz="-0.029 0 0"/>
      <mass value=".03522"/>
      <inertia ixx="0.000021977" ixy="0.000000082" ixz="-0.000000063" iyy="0.000017473" iyz="0.000000067" izz="0.000021078"/>
    </inertial>
    <visual>
      <geometry>
        <mesh filename="package://eigenbot/meshes/Bendy Out.STL" scale="1 1 1"/>
      </geometry>
      <origin rpy="0 0 0" xyz="0 0 0 "/>
    </visual>
    <collision>
      <geometry>
        <mesh filename="package://eigenbot/meshes/Bendy Out.STL" scale="1 1 1"/>
      </geometry>
      <origin rpy="0 0 0" xyz="0 0 0"/>
    </collision>
    <material name="black">
      <color rgba="0.1 0.1 0.1 1"/>
    </material>
  </link>
  <joint name="bendy_joint_M9_S9" type="revolute">
    <parent link="bendy_input_M9_S9"/>
    <child link="bendy_output_M9_S9"/>
    <origin rpy="0 0 0" xyz="-0.049 0 0"/>
    <axis xyz="0 1 0"/>
    <limit effort="100.0" lower="-1.57079632679" upper="1.57079632679" velocity="5"/>
  </joint>
  <link name="bendy_input_M10_S10">
    <inertial>
      <origin rpy="0 0 0" xyz="-0.023 0 0"/>
      <mass value="0.13536"/>
      <inertia ixx="0.000047004" ixy="-0.000000049" ixz="0.000000017" iyy="0.000068413" iyz="0.000000009" izz="0.000070686"/>
    </inertial>
    <visual>
      <geometry>
        <mesh filename="package://eigenbot/meshes/Bendy In.STL" scale="1 1 1"/>
      </geometry>
    </visual>
    <collision>
      <geometry>
        <mesh filename="package://eigenbot/meshes/Bendy In.STL" scale="1 1 1"/>
      </geometry>
    </collision>
    <material name="black">
      <color rgba="0.1 0.1 0.1 1"/>
    </material>
  </link>
  <link name="bendy_output_M10_S10">
    <inertial>
      <origin rpy="0 0 0" xyz="-0.029 0 0"/>
      <mass value=".03522"/>
      <inertia ixx="0.000021977" ixy="0.000000082" ixz="-0.000000063" iyy="0.000017473" iyz="0.000000067" izz="0.000021078"/>
    </inertial>
    <visual>
      <geometry>
        <mesh filename="package://eigenbot/meshes/Bendy Out.STL" scale="1 1 1"/>
      </geometry>
      <origin rpy="0 0 0" xyz="0 0 0 "/>
    </visual>
    <collision>
      <geometry>
        <mesh filename="package://eigenbot/meshes/Bendy Out.STL" scale="1 1 1"/>
      </geometry>
      <origin rpy="0 0 0" xyz="0 0 0"/>
    </collision>
    <material name="black">
      <color rgba="0.1 0.1 0.1 1"/>
    </material>
  </link>
  <joint name="bendy_joint_M10_S10" type="revolute">
    <parent link="bendy_input_M10_S10"/>
    <child link="bendy_output_M10_S10"/>
    <origin rpy="0 0 0" xyz="-0.049 0 0"/>
    <axis xyz="0 1 0"/>
    <limit effort="100.0" lower="-1.57079632679" upper="1.57079632679" velocity="5"/>
  </joint>
  <link name="bendy_input_M11_S11">
    <inertial>
      <origin rpy="0 0 0" xyz="-0.023 0 0"/>
      <mass value="0.13536"/>
      <inertia ixx="0.000047004" ixy="-0.000000049" ixz="0.000000017" iyy="0.000068413" iyz="0.000000009" izz="0.000070686"/>
    </inertial>
    <visual>
      <geometry>
        <mesh filename="package://eigenbot/meshes/Bendy In.STL" scale="1 1 1"/>
      </geometry>
    </visual>
    <collision>
      <geometry>
        <mesh filename="package://eigenbot/meshes/Bendy In.STL" scale="1 1 1"/>
      </geometry>
    </collision>
    <material name="black">
      <color rgba="0.1 0.1 0.1 1"/>
    </material>
  </link>
  <link name="bendy_output_M11_S11">
    <inertial>
      <origin rpy="0 0 0" xyz="-0.029 0 0"/>
      <mass value=".03522"/>
      <inertia ixx="0.000021977" ixy="0.000000082" ixz="-0.000000063" iyy="0.000017473" iyz="0.000000067" izz="0.000021078"/>
    </inertial>
    <visual>
      <geometry>
        <mesh filename="package://eigenbot/meshes/Bendy Out.STL" scale="1 1 1"/>
      </geometry>
      <origin rpy="0 0 0" xyz="0 0 0 "/>
    </visual>
    <collision>
      <geometry>
        <mesh filename="package://eigenbot/meshes/Bendy Out.STL" scale="1 1 1"/>
      </geometry>
      <origin rpy="0 0 0" xyz="0 0 0"/>
    </collision>
    <material name="black">
      <color rgba="0.1 0.1 0.1 1"/>
    </material>
  </link>
  <joint name="bendy_joint_M11_S11" type="revolute">
    <parent link="bendy_input_M11_S11"/>
    <child link="bendy_output_M11_S11"/>
    <origin rpy="0 0 0" xyz="-0.049 0 0"/>
    <axis xyz="0 1 0"/>
    <limit effort="100.0" lower="-1.57079632679" upper="1.57079632679" velocity="5"/>
  </joint>
  <link name="bendy_input_M12_S12">
    <inertial>
      <origin rpy="0 0 0" xyz="-0.023 0 0"/>
      <mass value="0.13536"/>
      <inertia ixx="0.000047004" ixy="-0.000000049" ixz="0.000000017" iyy="0.000068413" iyz="0.000000009" izz="0.000070686"/>
    </inertial>
    <visual>
      <geometry>
        <mesh filename="package://eigenbot/meshes/Bendy In.STL" scale="1 1 1"/>
      </geometry>
    </visual>
    <collision>
      <geometry>
        <mesh filename="package://eigenbot/meshes/Bendy In.STL" scale="1 1 1"/>
      </geometry>
    </collision>
    <material name="black">
      <color rgba="0.1 0.1 0.1 1"/>
    </material>
  </link>
  <link name="bendy_output_M12_S12">
    <inertial>
      <origin rpy="0 0 0" xyz="-0.029 0 0"/>
      <mass value=".03522"/>
      <inertia ixx="0.000021977" ixy="0.000000082" ixz="-0.000000063" iyy="0.000017473" iyz="0.000000067" izz="0.000021078"/>
    </inertial>
    <visual>
      <geometry>
        <mesh filename="package://eigenbot/meshes/Bendy Out.STL" scale="1 1 1"/>
      </geometry>
      <origin rpy="0 0 0" xyz="0 0 0 "/>
    </visual>
    <collision>
      <geometry>
        <mesh filename="package://eigenbot/meshes/Bendy Out.STL" scale="1 1 1"/>
      </geometry>
      <origin rpy="0 0 0" xyz="0 0 0"/>
    </collision>
    <material name="black">
      <color rgba="0.1 0.1 0.1 1"/>
    </material>
  </link>
  <joint name="bendy_joint_M12_S12" type="revolute">
    <parent link="bendy_input_M12_S12"/>
    <child link="bendy_output_M12_S12"/>
    <origin rpy="0 0 0" xyz="-0.049 0 0"/>
    <axis xyz="0 1 0"/>
    <limit effort="100.0" lower="-1.57079632679" upper="1.57079632679" velocity="5"/>
  </joint>
  <link name="bendy_input_M13_S13">
    <inertial>
      <origin rpy="0 0 0" xyz="-0.023 0 0"/>
      <mass value="0.13536"/>
      <inertia ixx="0.000047004" ixy="-0.000000049" ixz="0.000000017" iyy="0.000068413" iyz="0.000000009" izz="0.000070686"/>
    </inertial>
    <visual>
      <geometry>
        <mesh filename="package://eigenbot/meshes/Bendy In.STL" scale="1 1 1"/>
      </geometry>
    </visual>
    <collision>
      <geometry>
        <mesh filename="package://eigenbot/meshes/Bendy In.STL" scale="1 1 1"/>
      </geometry>
    </collision>
    <material name="black">
      <color rgba="0.1 0.1 0.1 1"/>
    </material>
  </link>
  <link name="bendy_output_M13_S13">
    <inertial>
      <origin rpy="0 0 0" xyz="-0.029 0 0"/>
      <mass value=".03522"/>
      <inertia ixx="0.000021977" ixy="0.000000082" ixz="-0.000000063" iyy="0.000017473" iyz="0.000000067" izz="0.000021078"/>
    </inertial>
    <visual>
      <geometry>
        <mesh filename="package://eigenbot/meshes/Bendy Out.STL" scale="1 1 1"/>
      </geometry>
      <origin rpy="0 0 0" xyz="0 0 0 "/>
    </visual>
    <collision>
      <geometry>
        <mesh filename="package://eigenbot/meshes/Bendy Out.STL" scale="1 1 1"/>
      </geometry>
      <origin rpy="0 0 0" xyz="0 0 0"/>
    </collision>
    <material name="black">
      <color rgba="0.1 0.1 0.1 1"/>
    </material>
  </link>
  <joint name="bendy_joint_M13_S13" type="revolute">
    <parent link="bendy_input_M13_S13"/>
    <child link="bendy_output_M13_S13"/>
    <origin rpy="0 0 0" xyz="-0.049 0 0"/>
    <axis xyz="0 1 0"/>
    <limit effort="100.0" lower="-1.57079632679" upper="1.57079632679" velocity="5"/>
  </joint>
  <link name="bendy_input_M14_S14">
    <inertial>
      <origin rpy="0 0 0" xyz="-0.023 0 0"/>
      <mass value="0.13536"/>
      <inertia ixx="0.000047004" ixy="-0.000000049" ixz="0.000000017" iyy="0.000068413" iyz="0.000000009" izz="0.000070686"/>
    </inertial>
    <visual>
      <geometry>
        <mesh filename="package://eigenbot/meshes/Bendy In.STL" scale="1 1 1"/>
      </geometry>
    </visual>
    <collision>
      <geometry>
        <mesh filename="package://eigenbot/meshes/Bendy In.STL" scale="1 1 1"/>
      </geometry>
    </collision>
    <material name="black">
      <color rgba="0.1 0.1 0.1 1"/>
    </material>
  </link>
  <link name="bendy_output_M14_S14">
    <inertial>
      <origin rpy="0 0 0" xyz="-0.029 0 0"/>
      <mass value=".03522"/>
      <inertia ixx="0.000021977" ixy="0.000000082" ixz="-0.000000063" iyy="0.000017473" iyz="0.000000067" izz="0.000021078"/>
    </inertial>
    <visual>
      <geometry>
        <mesh filename="package://eigenbot/meshes/Bendy Out.STL" scale="1 1 1"/>
      </geometry>
      <origin rpy="0 0 0" xyz="0 0 0 "/>
    </visual>
    <collision>
      <geometry>
        <mesh filename="package://eigenbot/meshes/Bendy Out.STL" scale="1 1 1"/>
      </geometry>
      <origin rpy="0 0 0" xyz="0 0 0"/>
    </collision>
    <material name="black">
      <color rgba="0.1 0.1 0.1 1"/>
    </material>
  </link>
  <joint name="bendy_joint_M14_S14" type="revolute">
    <parent link="bendy_input_M14_S14"/>
    <child link="bendy_output_M14_S14"/>
    <origin rpy="0 0 0" xyz="-0.049 0 0"/>
    <axis xyz="0 1 0"/>
    <limit effort="100.0" lower="-1.57079632679" upper="1.57079632679" velocity="5"/>
  </joint>
  <link name="bendy_input_M15_S15">
    <inertial>
      <origin rpy="0 0 0" xyz="-0.023 0 0"/>
      <mass value="0.13536"/>
      <inertia ixx="0.000047004" ixy="-0.000000049" ixz="0.000000017" iyy="0.000068413" iyz="0.000000009" izz="0.000070686"/>
    </inertial>
    <visual>
      <geometry>
        <mesh filename="package://eigenbot/meshes/Bendy In.STL" scale="1 1 1"/>
      </geometry>
    </visual>
    <collision>
      <geometry>
        <mesh filename="package://eigenbot/meshes/Bendy In.STL" scale="1 1 1"/>
      </geometry>
    </collision>
    <material name="black">
      <color rgba="0.1 0.1 0.1 1"/>
    </material>
  </link>
  <link name="bendy_output_M15_S15">
    <inertial>
      <origin rpy="0 0 0" xyz="-0.029 0 0"/>
      <mass value=".03522"/>
      <inertia ixx="0.000021977" ixy="0.000000082" ixz="-0.000000063" iyy="0.000017473" iyz="0.000000067" izz="0.000021078"/>
    </inertial>
    <visual>
      <geometry>
        <mesh filename="package://eigenbot/meshes/Bendy Out.STL" scale="1 1 1"/>
      </geometry>
      <origin rpy="0 0 0" xyz="0 0 0 "/>
    </visual>
    <collision>
      <geometry>
        <mesh filename="package://eigenbot/meshes/Bendy Out.STL" scale="1 1 1"/>
      </geometry>
      <origin rpy="0 0 0" xyz="0 0 0"/>
    </collision>
    <material name="black">
      <color rgba="0.1 0.1 0.1 1"/>
    </material>
  </link>
  <joint name="bendy_joint_M15_S15" type="revolute">
    <parent link="bendy_input_M15_S15"/>
    <child link="bendy_output_M15_S15"/>
    <origin rpy="0 0 0" xyz="-0.049 0 0"/>
    <axis xyz="0 1 0"/>
    <limit effort="100.0" lower="-1.57079632679" upper="1.57079632679" velocity="5"/>
  </joint>
  <link name="bendy_input_M16_S16">
    <inertial>
      <origin rpy="0 0 0" xyz="-0.023 0 0"/>
      <mass value="0.13536"/>
      <inertia ixx="0.000047004" ixy="-0.000000049" ixz="0.000000017" iyy="0.000068413" iyz="0.000000009" izz="0.000070686"/>
    </inertial>
    <visual>
      <geometry>
        <mesh filename="package://eigenbot/meshes/Bendy In.STL" scale="1 1 1"/>
      </geometry>
    </visual>
    <collision>
      <geometry>
        <mesh filename="package://eigenbot/meshes/Bendy In.STL" scale="1 1 1"/>
      </geometry>
    </collision>
    <material name="black">
      <color rgba="0.1 0.1 0.1 1"/>
    </material>
  </link>
  <link name="bendy_output_M16_S16">
    <inertial>
      <origin rpy="0 0 0" xyz="-0.029 0 0"/>
      <mass value=".03522"/>
      <inertia ixx="0.000021977" ixy="0.000000082" ixz="-0.000000063" iyy="0.000017473" iyz="0.000000067" izz="0.000021078"/>
    </inertial>
    <visual>
      <geometry>
        <mesh filename="package://eigenbot/meshes/Bendy Out.STL" scale="1 1 1"/>
      </geometry>
      <origin rpy="0 0 0" xyz="0 0 0 "/>
    </visual>
    <collision>
      <geometry>
        <mesh filename="package://eigenbot/meshes/Bendy Out.STL" scale="1 1 1"/>
      </geometry>
      <origin rpy="0 0 0" xyz="0 0 0"/>
    </collision>
    <material name="black">
      <color rgba="0.1 0.1 0.1 1"/>
    </material>
  </link>
  <joint name="bendy_joint_M16_S16" type="revolute">
    <parent link="bendy_input_M16_S16"/>
    <child link="bendy_output_M16_S16"/>
    <origin rpy="0 0 0" xyz="-0.049 0 0"/>
    <axis xyz="0 1 0"/>
    <limit effort="100.0" lower="-1.57079632679" upper="1.57079632679" velocity="5"/>
  </joint>
  <link name="bendy_input_M17_S17">
    <inertial>
      <origin rpy="0 0 0" xyz="-0.023 0 0"/>
      <mass value="0.13536"/>
      <inertia ixx="0.000047004" ixy="-0.000000049" ixz="0.000000017" iyy="0.000068413" iyz="0.000000009" izz="0.000070686"/>
    </inertial>
    <visual>
      <geometry>
        <mesh filename="package://eigenbot/meshes/Bendy In.STL" scale="1 1 1"/>
      </geometry>
    </visual>
    <collision>
      <geometry>
        <mesh filename="package://eigenbot/meshes/Bendy In.STL" scale="1 1 1"/>
      </geometry>
    </collision>
    <material name="black">
      <color rgba="0.1 0.1 0.1 1"/>
    </material>
  </link>
  <link name="bendy_output_M17_S17">
    <inertial>
      <origin rpy="0 0 0" xyz="-0.029 0 0"/>
      <mass value=".03522"/>
      <inertia ixx="0.000021977" ixy="0.000000082" ixz="-0.000000063" iyy="0.000017473" iyz="0.000000067" izz="0.000021078"/>
    </inertial>
    <visual>
      <geometry>
        <mesh filename="package://eigenbot/meshes/Bendy Out.STL" scale="1 1 1"/>
      </geometry>
      <origin rpy="0 0 0" xyz="0 0 0 "/>
    </visual>
    <collision>
      <geometry>
        <mesh filename="package://eigenbot/meshes/Bendy Out.STL" scale="1 1 1"/>
      </geometry>
      <origin rpy="0 0 0" xyz="0 0 0"/>
    </collision>
    <material name="black">
      <color rgba="0.1 0.1 0.1 1"/>
    </material>
  </link>
  <joint name="bendy_joint_M17_S17" type="revolute">
    <parent link="bendy_input_M17_S17"/>
    <child link="bendy_output_M17_S17"/>
    <origin rpy="0 0 0" xyz="-0.049 0 0"/>
    <axis xyz="0 1 0"/>
    <limit effort="100.0" lower="-1.57079632679" upper="1.57079632679" velocity="5"/>
  </joint>
  <link name="bendy_input_M18_S18">
    <inertial>
      <origin rpy="0 0 0" xyz="-0.023 0 0"/>
      <mass value="0.13536"/>
      <inertia ixx="0.000047004" ixy="-0.000000049" ixz="0.000000017" iyy="0.000068413" iyz="0.000000009" izz="0.000070686"/>
    </inertial>
    <visual>
      <geometry>
        <mesh filename="package://eigenbot/meshes/Bendy In.STL" scale="1 1 1"/>
      </geometry>
    </visual>
    <collision>
      <geometry>
        <mesh filename="package://eigenbot/meshes/Bendy In.STL" scale="1 1 1"/>
      </geometry>
    </collision>
    <material name="black">
      <color rgba="0.1 0.1 0.1 1"/>
    </material>
  </link>
  <link name="bendy_output_M18_S18">
    <inertial>
      <origin rpy="0 0 0" xyz="-0.029 0 0"/>
      <mass value=".03522"/>
      <inertia ixx="0.000021977" ixy="0.000000082" ixz="-0.000000063" iyy="0.000017473" iyz="0.000000067" izz="0.000021078"/>
    </inertial>
    <visual>
      <geometry>
        <mesh filename="package://eigenbot/meshes/Bendy Out.STL" scale="1 1 1"/>
      </geometry>
      <origin rpy="0 0 0" xyz="0 0 0 "/>
    </visual>
    <collision>
      <geometry>
        <mesh filename="package://eigenbot/meshes/Bendy Out.STL" scale="1 1 1"/>
      </geometry>
      <origin rpy="0 0 0" xyz="0 0 0"/>
    </collision>
    <material name="black">
      <color rgba="0.1 0.1 0.1 1"/>
    </material>
  </link>
  <joint name="bendy_joint_M18_S18" type="revolute">
    <parent link="bendy_input_M18_S18"/>
    <child link="bendy_output_M18_S18"/>
    <origin rpy="0 0 0" xyz="-0.049 0 0"/>
    <axis xyz="0 1 0"/>
    <limit effort="100.0" lower="-1.57079632679" upper="1.57079632679" velocity="5"/>
  </joint>
  <link name="static_elbow_M19_S19">
    <inertial>
      <origin rpy="0 0 0" xyz="-0.03148 0.00004 -0.01437"/>
      <mass value="0.06766"/>
      <inertia ixx="0.000052397" ixy="-0.0000001126" ixz="0.000015681" iyy="0.000065586" iyz="-0.000000082" izz="0.000053626"/>
    </inertial>
    <visual>
      <geometry>
        <mesh filename="package://eigenbot/meshes/Elbow.STL" scale="1 1 1"/>
      </geometry>
    </visual>
    <collision>
      <geometry>
        <mesh filename="package://eigenbot/meshes/Elbow.STL" scale="1 1 1"/>
      </geometry>
    </collision>
    <material name="black">
      <color rgba="0.1 0.1 0.1 1"/>
    </material>
  </link>
  <link name="static_elbow_M20_S20">
    <inertial>
      <origin rpy="0 0 0" xyz="-0.03148 0.00004 -0.01437"/>
      <mass value="0.06766"/>
      <inertia ixx="0.000052397" ixy="-0.0000001126" ixz="0.000015681" iyy="0.000065586" iyz="-0.000000082" izz="0.000053626"/>
    </inertial>
    <visual>
      <geometry>
        <mesh filename="package://eigenbot/meshes/Elbow.STL" scale="1 1 1"/>
      </geometry>
    </visual>
    <collision>
      <geometry>
        <mesh filename="package://eigenbot/meshes/Elbow.STL" scale="1 1 1"/>
      </geometry>
    </collision>
    <material name="black">
      <color rgba="0.1 0.1 0.1 1"/>
    </material>
  </link>
  <link name="static_elbow_M21_S21">
    <inertial>
      <origin rpy="0 0 0" xyz="-0.03148 0.00004 -0.01437"/>
      <mass value="0.06766"/>
      <inertia ixx="0.000052397" ixy="-0.0000001126" ixz="0.000015681" iyy="0.000065586" iyz="-0.000000082" izz="0.000053626"/>
    </inertial>
    <visual>
      <geometry>
        <mesh filename="package://eigenbot/meshes/Elbow.STL" scale="1 1 1"/>
      </geometry>
    </visual>
    <collision>
      <geometry>
        <mesh filename="package://eigenbot/meshes/Elbow.STL" scale="1 1 1"/>
      </geometry>
    </collision>
    <material name="black">
      <color rgba="0.1 0.1 0.1 1"/>
    </material>
  </link>
  <link name="static_elbow_M22_S22">
    <inertial>
      <origin rpy="0 0 0" xyz="-0.03148 0.00004 -0.01437"/>
      <mass value="0.06766"/>
      <inertia ixx="0.000052397" ixy="-0.0000001126" ixz="0.000015681" iyy="0.000065586" iyz="-0.000000082" izz="0.000053626"/>
    </inertial>
    <visual>
      <geometry>
        <mesh filename="package://eigenbot/meshes/Elbow.STL" scale="1 1 1"/>
      </geometry>
    </visual>
    <collision>
      <geometry>
        <mesh filename="package://eigenbot/meshes/Elbow.STL" scale="1 1 1"/>
      </geometry>
    </collision>
    <material name="black">
      <color rgba="0.1 0.1 0.1 1"/>
    </material>
  </link>
  <link name="static_elbow_M23_S23">
    <inertial>
      <origin rpy="0 0 0" xyz="-0.03148 0.00004 -0.01437"/>
      <mass value="0.06766"/>
      <inertia ixx="0.000052397" ixy="-0.0000001126" ixz="0.000015681" iyy="0.000065586" iyz="-0.000000082" izz="0.000053626"/>
    </inertial>
    <visual>
      <geometry>
        <mesh filename="package://eigenbot/meshes/Elbow.STL" scale="1 1 1"/>
      </geometry>
    </visual>
    <collision>
      <geometry>
        <mesh filename="package://eigenbot/meshes/Elbow.STL" scale="1 1 1"/>
      </geometry>
    </collision>
    <material name="black">
      <color rgba="0.1 0.1 0.1 1"/>
    </material>
  </link>
  <link name="static_elbow_M24_S24">
    <inertial>
      <origin rpy="0 0 0" xyz="-0.03148 0.00004 -0.01437"/>
      <mass value="0.06766"/>
      <inertia ixx="0.000052397" ixy="-0.0000001126" ixz="0.000015681" iyy="0.000065586" iyz="-0.000000082" izz="0.000053626"/>
    </inertial>
    <visual>
      <geometry>
        <mesh filename="package://eigenbot/meshes/Elbow.STL" scale="1 1 1"/>
      </geometry>
    </visual>
    <collision>
      <geometry>
        <mesh filename="package://eigenbot/meshes/Elbow.STL" scale="1 1 1"/>
      </geometry>
    </collision>
    <material name="black">
      <color rgba="0.1 0.1 0.1 1"/>
    </material>
  </link>
  <link name="foot_input_M25_S25">
    <inertial>
      <origin rpy="0 0 0" xyz="-0.03918 0 0"/>
      <mass value="0.04967"/>
      <inertia ixx="0.0000361" ixy="0" ixz="0" iyy="0.0000434" iyz="0" izz="0.0000434"/>
    </inertial>
    <visual>
      <geometry>
        <mesh filename="package://eigenbot/meshes/Foot.STL" scale=" 1 1 1 "/>
      </geometry>
    </visual>
    <collision>
      <geometry>
        <mesh filename="package://eigenbot/meshes/Foot.STL" scale=" 1 1 1 "/>
      </geometry>
    </collision>
    <material name="black">
      <color rgba="0.1 0.1 0.1 1"/>
    </material>
  </link>
  <link name="foot_input_M26_S26">
    <inertial>
      <origin rpy="0 0 0" xyz="-0.03918 0 0"/>
      <mass value="0.04967"/>
      <inertia ixx="0.0000361" ixy="0" ixz="0" iyy="0.0000434" iyz="0" izz="0.0000434"/>
    </inertial>
    <visual>
      <geometry>
        <mesh filename="package://eigenbot/meshes/Foot.STL" scale=" 1 1 1 "/>
      </geometry>
    </visual>
    <collision>
      <geometry>
        <mesh filename="package://eigenbot/meshes/Foot.STL" scale=" 1 1 1 "/>
      </geometry>
    </collision>
    <material name="black">
      <color rgba="0.1 0.1 0.1 1"/>
    </material>
  </link>
  <link name="foot_input_M27_S27">
    <inertial>
      <origin rpy="0 0 0" xyz="-0.03918 0 0"/>
      <mass value="0.04967"/>
      <inertia ixx="0.0000361" ixy="0" ixz="0" iyy="0.0000434" iyz="0" izz="0.0000434"/>
    </inertial>
    <visual>
      <geometry>
        <mesh filename="package://eigenbot/meshes/Foot.STL" scale=" 1 1 1 "/>
      </geometry>
    </visual>
    <collision>
      <geometry>
        <mesh filename="package://eigenbot/meshes/Foot.STL" scale=" 1 1 1 "/>
      </geometry>
    </collision>
    <material name="black">
      <color rgba="0.1 0.1 0.1 1"/>
    </material>
  </link>
  <link name="foot_input_M28_S28">
    <inertial>
      <origin rpy="0 0 0" xyz="-0.03918 0 0"/>
      <mass value="0.04967"/>
      <inertia ixx="0.0000361" ixy="0" ixz="0" iyy="0.0000434" iyz="0" izz="0.0000434"/>
    </inertial>
    <visual>
      <geometry>
        <mesh filename="package://eigenbot/meshes/Foot.STL" scale=" 1 1 1 "/>
      </geometry>
    </visual>
    <collision>
      <geometry>
        <mesh filename="package://eigenbot/meshes/Foot.STL" scale=" 1 1 1 "/>
      </geometry>
    </collision>
    <material name="black">
      <color rgba="0.1 0.1 0.1 1"/>
    </material>
  </link>
  <link name="foot_input_M29_S29">
    <inertial>
      <origin rpy="0 0 0" xyz="-0.03918 0 0"/>
      <mass value="0.04967"/>
      <inertia ixx="0.0000361" ixy="0" ixz="0" iyy="0.0000434" iyz="0" izz="0.0000434"/>
    </inertial>
    <visual>
      <geometry>
        <mesh filename="package://eigenbot/meshes/Foot.STL" scale=" 1 1 1 "/>
      </geometry>
    </visual>
    <collision>
      <geometry>
        <mesh filename="package://eigenbot/meshes/Foot.STL" scale=" 1 1 1 "/>
      </geometry>
    </collision>
    <material name="black">
      <color rgba="0.1 0.1 0.1 1"/>
    </material>
  </link>
  <link name="foot_input_M30_S30">
    <inertial>
      <origin rpy="0 0 0" xyz="-0.03918 0 0"/>
      <mass value="0.04967"/>
      <inertia ixx="0.0000361" ixy="0" ixz="0" iyy="0.0000434" iyz="0" izz="0.0000434"/>
    </inertial>
    <visual>
      <geometry>
        <mesh filename="package://eigenbot/meshes/Foot.STL" scale=" 1 1 1 "/>
      </geometry>
    </visual>
    <collision>
      <geometry>
        <mesh filename="package://eigenbot/meshes/Foot.STL" scale=" 1 1 1 "/>
      </geometry>
    </collision>
    <material name="black">
      <color rgba="0.1 0.1 0.1 1"/>
    </material>
  </link>
  <joint name="connection_0_attachment" type="fixed">
    <origin rpy="0 0 -1.57079632679" xyz="-0.041 0.067 -0.13"/>
    <parent link="eigenbody_M0_S0"/>
    <child link="bendy_input_M1_S1"/>
  </joint>
  <joint name="connection_1_attachment" type="fixed">
    <origin rpy="0 0 -1.57079632679" xyz="-0.041 0.067 -0.04"/>
    <parent link="eigenbody_M0_S0"/>
    <child link="bendy_input_M2_S2"/>
  </joint>
  <joint name="connection_2_attachment" type="fixed">
    <origin rpy="0 0 -1.57079632679" xyz="-0.041 0.067 0.05"/>
    <parent link="eigenbody_M0_S0"/>
    <child link="bendy_input_M3_S3"/>
  </joint>
  <joint name="connection_3_attachment" type="fixed">
    <origin rpy="0 0 1.57079632679" xyz="-0.041 -0.067 -0.13"/>
    <parent link="eigenbody_M0_S0"/>
    <child link="bendy_input_M4_S4"/>
  </joint>
  <joint name="connection_4_attachment" type="fixed">
    <origin rpy="0 0 1.57079632679" xyz="-0.041 -0.067 -0.04"/>
    <parent link="eigenbody_M0_S0"/>
    <child link="bendy_input_M5_S5"/>
  </joint>
  <joint name="connection_5_attachment" type="fixed">
    <origin rpy="0 0 1.57079632679" xyz="-0.041 -0.067 0.05"/>
    <parent link="eigenbody_M0_S0"/>
    <child link="bendy_input_M6_S6"/>
  </joint>
  <joint name="connection_6_attachment" type="fixed">
    <origin rpy="4.71238898038 0 0" xyz="-0.036 0 0"/>
    <parent link="bendy_output_M1_S1"/>
    <child link="bendy_input_M7_S7"/>
  </joint>
  <joint name="connection_7_attachment" type="fixed">
    <origin rpy="4.71238898038 0 0" xyz="-0.036 0 0"/>
    <parent link="bendy_output_M2_S2"/>
    <child link="bendy_input_M8_S8"/>
  </joint>
  <joint name="connection_8_attachment" type="fixed">
    <origin rpy="4.71238898038 0 0" xyz="-0.036 0 0"/>
    <parent link="bendy_output_M3_S3"/>
    <child link="bendy_input_M9_S9"/>
  </joint>
  <joint name="connection_9_attachment" type="fixed">
    <origin rpy="1.57079632679 0 0" xyz="-0.036 0 0"/>
    <parent link="bendy_output_M4_S4"/>
    <child link="bendy_input_M10_S10"/>
  </joint>
  <joint name="connection_10_attachment" type="fixed">
    <origin rpy="1.57079632679 0 0" xyz="-0.036 0 0"/>
    <parent link="bendy_output_M5_S5"/>
    <child link="bendy_input_M11_S11"/>
  </joint>
  <joint name="connection_11_attachment" type="fixed">
    <origin rpy="1.57079632679 0 0" xyz="-0.036 0 0"/>
    <parent link="bendy_output_M6_S6"/>
    <child link="bendy_input_M12_S12"/>
  </joint>
  <joint name="connection_12_attachment" type="fixed">
    <origin rpy="0 0 0" xyz="-0.036 0 0"/>
    <parent link="bendy_output_M7_S7"/>
    <child link="bendy_input_M13_S13"/>
  </joint>
  <joint name="connection_13_attachment" type="fixed">
    <origin rpy="0 0 0" xyz="-0.036 0 0"/>
    <parent link="bendy_output_M8_S8"/>
    <child link="bendy_input_M14_S14"/>
  </joint>
  <joint name="connection_14_attachment" type="fixed">
    <origin rpy="0 0 0" xyz="-0.036 0 0"/>
    <parent link="bendy_output_M9_S9"/>
    <child link="bendy_input_M15_S15"/>
  </joint>
  <joint name="connection_15_attachment" type="fixed">
    <origin rpy="0 0 0" xyz="-0.036 0 0"/>
    <parent link="bendy_output_M10_S10"/>
    <child link="bendy_input_M16_S16"/>
  </joint>
  <joint name="connection_16_attachment" type="fixed">
    <origin rpy="0 0 0" xyz="-0.036 0 0"/>
    <parent link="bendy_output_M11_S11"/>
    <child link="bendy_input_M17_S17"/>
  </joint>
  <joint name="connection_17_attachment" type="fixed">
    <origin rpy="0 0 0" xyz="-0.036 0 0"/>
    <parent link="bendy_output_M12_S12"/>
    <child link="bendy_input_M18_S18"/>
  </joint>
  <joint name="connection_18_attachment" type="fixed">
    <origin rpy="0 0 0" xyz="-0.036 0 0"/>
    <parent link="bendy_output_M13_S13"/>
    <child link="static_elbow_M19_S19"/>
  </joint>
  <joint name="connection_19_attachment" type="fixed">
    <origin rpy="0 0 0" xyz="-0.036 0 0"/>
    <parent link="bendy_output_M14_S14"/>
    <child link="static_elbow_M20_S20"/>
  </joint>
  <joint name="connection_20_attachment" type="fixed">
    <origin rpy="0 0 0" xyz="-0.036 0 0"/>
    <parent link="bendy_output_M15_S15"/>
    <child link="static_elbow_M21_S21"/>
  </joint>
  <joint name="connection_21_attachment" type="fixed">
    <origin rpy="0 0 0" xyz="-0.036 0 0"/>
    <parent link="bendy_output_M16_S16"/>
    <child link="static_elbow_M22_S22"/>
  </joint>
  <joint name="connection_22_attachment" type="fixed">
    <origin rpy="0 0 0" xyz="-0.036 0 0"/>
    <parent link="bendy_output_M17_S17"/>
    <child link="static_elbow_M23_S23"/>
  </joint>
  <joint name="connection_23_attachment" type="fixed">
    <origin rpy="0 0 0" xyz="-0.036 0 0"/>
    <parent link="bendy_output_M18_S18"/>
    <child link="static_elbow_M24_S24"/>
  </joint>
  <joint name="connection_24_attachment" type="fixed">
    <origin rpy="0 -1.57079632679 0" xyz="-0.0455 0 -0.0375"/>
    <parent link="static_elbow_M19_S19"/>
    <child link="foot_input_M25_S25"/>
  </joint>
  <joint name="connection_25_attachment" type="fixed">
    <origin rpy="0 -1.57079632679 0" xyz="-0.0455 0 -0.0375"/>
    <parent link="static_elbow_M20_S20"/>
    <child link="foot_input_M26_S26"/>
  </joint>
  <joint name="connection_26_attachment" type="fixed">
    <origin rpy="0 -1.57079632679 0" xyz="-0.0455 0 -0.0375"/>
    <parent link="static_elbow_M21_S21"/>
    <child link="foot_input_M27_S27"/>
  </joint>
  <joint name="connection_27_attachment" type="fixed">
    <origin rpy="0 -1.57079632679 0" xyz="-0.0455 0 -0.0375"/>
    <parent link="static_elbow_M22_S22"/>
    <child link="foot_input_M28_S28"/>
  </joint>
  <joint name="connection_28_attachment" type="fixed">
    <origin rpy="0 -1.57079632679 0" xyz="-0.0455 0 -0.0375"/>
    <parent link="static_elbow_M23_S23"/>
    <child link="foot_input_M29_S29"/>
  </joint>
  <joint name="connection_29_attachment" type="fixed">
    <origin rpy="0 -1.57079632679 0" xyz="-0.0455 0 -0.0375"/>
    <parent link="static_elbow_M24_S24"/>
    <child link="foot_input_M30_S30"/>
  </joint>
</robot>
