<?xml version="1.0"?>
<robot xmlns:xacro="http://www.ros.org/wiki/xacro">
<!-- TODO: correct this to the right offsets from CAD -->
<xacro:macro name="torsional_module" params="module_label">
  
    <link name="torsional_input_${module_label}">
      <inertial>
          <origin
            xyz="-0.0412  0 -0.001"
            rpy="0 0 0" />
          <mass
            value=".2208" />        
          <inertia
            ixx="0.000090556"
            ixy="-0.00000055"
            ixz="0.000003602"
            iyy="0.000126583"
            iyz="0.000000021"
            izz="0.000119521" />
        </inertial>
      
        <visual>
          <geometry>
			<mesh
          filename="package://eigenbot/meshes/Torquey In.STL" scale="1 1 1" 
/>       
 </geometry>
        </visual>  
        
        <collision>
          <geometry>
			<mesh
          filename="package://eigenbot/meshes/Torquey In.STL" scale="1 1 1" 
/>              
</geometry>
        </collision>
        
    <material name="black">
      <color rgba="0.1 0.1 0.1 1"/>
    </material> 
      </link>
	  
	   <link name="torsional_output_${module_label}">
      
      <inertial>
          <origin
            xyz="-0.0026  0 0"
            rpy="0 0 0" />
          <mass
            value="0.0804" />
          <inertia
            ixx="0.000037098"
            ixy="-0.000000038"
            ixz="0.000000802"
            iyy="0.000025873"
            iyz="0.000000022"
            izz="0.000025138" />
        </inertial>
      
        <visual>

	<origin xyz="0 0 0" rpy="0 0 0" />

          <geometry>
			<mesh
          filename="package://eigenbot/meshes/Torquey Out.STL" scale="1 1 1" 
/>          </geometry>
        </visual>  
        
        <collision>
	<origin xyz="0 0 0" rpy="0 0 0" />

          <geometry>
			<mesh
          filename="package://eigenbot/meshes/Torquey Out.STL" scale="1 1 1" 
/>              </geometry>
        </collision>
        
       <material name="black">
      <color rgba="0.1 0.1 0.1 1"/>
    </material> 
      </link>
	  
	  
  <joint name="torsional_joint_${module_label}" type="continuous">
    <parent link="torsional_input_${module_label}"/>
    <child link="torsional_output_${module_label}"/>
    <origin xyz="-0.0695724 0 0" rpy="0 0 0" />
      <axis xyz="1 0 0"/> 
  </joint>
	  
	  
    </xacro:macro>
</robot>



